Workbook

Sheet KHACH HANG
A1: KẾ HOẠCH PHÂN BỔ DOANH SỐ 2017 TỈNH……..
A3: =S4 -> #REF! | G3: DOANH SỐ THỰC HIỆN THEO TỪNG THÁNG
A4: DS THEO TỪNG THÁNG | G4: =#REF! -> #REF! | H4: =#REF! -> #REF! | I4: =#REF! -> #REF! | J4: =#REF! -> #REF! | K4: =#REF! -> #REF! | L4: =#REF! -> #REF! | M4: =#REF! -> #REF! | N4: =#REF! -> #REF! | ... R4: =#REF! -> #REF! | S4: =SUM(G4:R4) -> #REF!
A5: NHÂN VIÊN | B5: TÊN KH | C5: TT | D5: PHÂN LOẠI SP | E5: SẢN PHẨM | F5: total | G5: 1 | H5: 2 | I5: 3 | J5: 4 | K5: 5 | L5: 6 | M5: 7 | N5: 8 | O5: 9 | P5: 10 | Q5: 11 | R5: 12 | S5: Grand Total | T5: TOTAL | W5: PHÂN LOẠI SP | X5: SẢN PHẨM | Y5: SẢN PHẨM | Z5: SẢN PHẨM | AA5: SẢN PHẨM | AB5: SẢN PHẨM | AC5: SẢN PHẨM | AD5: SẢN PHẨM
A6: VÕ ĐÔNG CUNG | B6: GIÁO CÔNG | C6: 1 | D6: =VLOOKUP(C6,DMSP!$A$1:$C$39,2,0) -> 1.TOBA XANH | E6: =VLOOKUP(C6,DMSP!$A$1:$C$39,3,0) -> TOBA XANH | F6: =S6 -> 0 | S6: =SUM(G6:R6) -> 0 | T6: =S43 -> 414 | V6: 1 | W6: =D6 -> 1.TOBA XANH | X6: =E6 -> TOBA XANH | Y6: =X6 -> TOBA XANH | Z6: =X7 -> HC BOOSTER | AA6: =X8 -> HC KING-ROOT | AB6: =X9 -> HAPPY FARM | AC6: =X10 -> WOW | AD6: =X11 -> KELPIT
C7: =C6+1 -> 2 | D7: =VLOOKUP(C7,DMSP!$A$1:$C$39,2,0) -> 2.HC | E7: =VLOOKUP(C7,DMSP!$A$1:$C$39,3,0) -> HC BOOSTER | F7: =S7 -> 11 | G7: 11 | S7: =SUM(G7:R7) -> 11 | V7: =V6+1 -> 2 | W7: =D7 -> 2.HC | X7: =E7 -> HC BOOSTER | Y7: SẢN PHẨM | Z7: SẢN PHẨM | AA7: SẢN PHẨM | AB7: SẢN PHẨM | AC7: SẢN PHẨM | AD7: SẢN PHẨM
C8: =C7+1 -> 3 | D8: =VLOOKUP(C8,DMSP!$A$1:$C$39,2,0) -> 2.HC | E8: =VLOOKUP(C8,DMSP!$A$1:$C$39,3,0) -> HC KING-ROOT | F8: =S8 -> 0 | S8: =SUM(G8:R8) -> 0 | V8: =V7+1 -> 3 | W8: =D8 -> 2.HC | X8: =E8 -> HC KING-ROOT | Y8: =X12 -> SI-K | Z8: =X13 -> SPRAY PHOS 620 | AA8: =X14 -> CHITOSAN | AB8: =X15 -> ĐẠM CÁ | AC8: =X16 -> ĐẠM TÔM | AD8: =X17 -> SUPERMIC
C9: =C8+1 -> 4 | D9: =VLOOKUP(C9,DMSP!$A$1:$C$39,2,0) -> 2.HC | E9: =VLOOKUP(C9,DMSP!$A$1:$C$39,3,0) -> HAPPY FARM | F9: =S9 -> 35 | G9: 35 | S9: =SUM(G9:R9) -> 35 | V9: =V8+1 -> 4 | W9: =D9 -> 2.HC | X9: =E9 -> HAPPY FARM | Y9: SẢN PHẨM | Z9: SẢN PHẨM | AA9: SẢN PHẨM | AB9: SẢN PHẨM | AC9: SẢN PHẨM | AD9: SẢN PHẨM
C10: =C9+1 -> 5 | D10: =VLOOKUP(C10,DMSP!$A$1:$C$39,2,0) -> 2.HC | E10: =VLOOKUP(C10,DMSP!$A$1:$C$39,3,0) -> WOW | F10: =S10 -> 0 | S10: =SUM(G10:R10) -> 0 | V10: =V9+1 -> 5 | W10: =D10 -> 2.HC | X10: =E10 -> WOW | Y10: =X18 -> CABO | Z10: =X19 -> F94 | AA10: =X20 -> F95 | AB10: =X21 -> THIOURE | AC10: =X22 -> TOBA JUM | AD10: =X23 -> TOBA NET
C11: =C10+1 -> 6 | D11: =VLOOKUP(C11,DMSP!$A$1:$C$39,2,0) -> 3.SPRAY | E11: =VLOOKUP(C11,DMSP!$A$1:$C$39,3,0) -> KELPIT | F11: =S11 -> 0 | S11: =SUM(G11:R11) -> 0 | V11: =V10+1 -> 6 | W11: =D11 -> 3.SPRAY | X11: =E11 -> KELPIT | Y11: SẢN PHẨM | Z11: SẢN PHẨM | AA11: SẢN PHẨM | AB11: SẢN PHẨM | AC11: SẢN PHẨM | AD11: SẢN PHẨM
C12: =C11+1 -> 7 | D12: =VLOOKUP(C12,DMSP!$A$1:$C$39,2,0) -> 3.SPRAY | E12: =VLOOKUP(C12,DMSP!$A$1:$C$39,3,0) -> SI-K | F12: =S12 -> 74 | K12: 25 | L12: 49 | S12: =SUM(G12:R12) -> 74 | V12: =V11+1 -> 7 | W12: =D12 -> 3.SPRAY | X12: =E12 -> SI-K | Y12: =X24 -> ABAFAX 1.8 | Z12: =X25 -> ABAFAX 3.6 | AA12: =X26 -> AZET | AB12: =X27 -> BACBA | AC12: =X28 -> BIOROSAMIL | AD12: =X29 -> COC 86
C13: =C12+1 -> 8 | D13: =VLOOKUP(C13,DMSP!$A$1:$C$39,2,0) -> 3.SPRAY | E13: =VLOOKUP(C13,DMSP!$A$1:$C$39,3,0) -> SPRAY PHOS 620 | F13: =S13 -> 23 | G13: 23 | S13: =SUM(G13:R13) -> 23 | V13: =V12+1 -> 8 | W13: =D13 -> 3.SPRAY | X13: =E13 -> SPRAY PHOS 620 | Y13: SẢN PHẨM | Z13: SẢN PHẨM | AA13: SẢN PHẨM | AB13: SẢN PHẨM | AC13: SẢN PHẨM | AD13: SẢN PHẨM
C14: =C13+1 -> 9 | D14: =VLOOKUP(C14,DMSP!$A$1:$C$39,2,0) -> 4.DƯỠNG RỄ | E14: =VLOOKUP(C14,DMSP!$A$1:$C$39,3,0) -> CHITOSAN | F14: =S14 -> 0 | S14: =SUM(G14:R14) -> 0 | V14: =V13+1 -> 9 | W14: =D14 -> 4.DƯỠNG RỄ | X14: =E14 -> CHITOSAN | Y14: =X30 -> HEXA 5 | Z14: =X31 -> TAMALA | AA14: =X32 -> KẼM VÀNG | AB14: =X33 -> KHÁC1 | AC14: =X34 -> REACH | AD14: =X35 -> RỬA RONG RÊU
C15: =C14+1 -> 10 | D15: =VLOOKUP(C15,DMSP!$A$1:$C$39,2,0) -> 4.DƯỠNG RỄ | E15: =VLOOKUP(C15,DMSP!$A$1:$C$39,3,0) -> ĐẠM CÁ | F15: =S15 -> 0 | S15: =SUM(G15:R15) -> 0 | V15: =V14+1 -> 10 | W15: =D15 -> 4.DƯỠNG RỄ | X15: =E15 -> ĐẠM CÁ | Y15: SẢN PHẨM | Z15: SẢN PHẨM | AA15: SẢN PHẨM | AB15: SẢN PHẨM | AC15: SẢN PHẨM | AD15: SẢN PHẨM
C16: =C15+1 -> 11 | D16: =VLOOKUP(C16,DMSP!$A$1:$C$39,2,0) -> 4.DƯỠNG RỄ | E16: =VLOOKUP(C16,DMSP!$A$1:$C$39,3,0) -> ĐẠM TÔM | F16: =S16 -> 0 | S16: =SUM(G16:R16) -> 0 | V16: =V15+1 -> 11 | W16: =D16 -> 4.DƯỠNG RỄ | X16: =E16 -> ĐẠM TÔM | Y16: =X36 -> TB BO | Z16: =X37 -> TB FRUIT | AA16: =X38 -> TB PHOS | AB16: =X39 -> TOBA BÁM DÍNH | AC16: =X40 -> VỌT HOA NHÃN | AD16: =X41 -> VỌT HOA XOÀI
C17: =C16+1 -> 12 | D17: =VLOOKUP(C17,DMSP!$A$1:$C$39,2,0) -> 4.DƯỠNG RỄ | E17: =VLOOKUP(C17,DMSP!$A$1:$C$39,3,0) -> SUPERMIC | F17: =S17 -> 88 | G17: 9 | J17: 35 | L17: 18 | Q17: 26 | S17: =SUM(G17:R17) -> 88 | V17: =V16+1 -> 12 | W17: =D17 -> 4.DƯỠNG RỄ | X17: =E17 -> SUPERMIC | Y17: SẢN PHẨM | Z17: SẢN PHẨM | AA17: SẢN PHẨM | AB17: SẢN PHẨM | AC17: SẢN PHẨM | AD17: SẢN PHẨM
C18: =C17+1 -> 13 | D18: =VLOOKUP(C18,DMSP!$A$1:$C$39,2,0) -> 5.TRUYỀN THỐNG | E18: =VLOOKUP(C18,DMSP!$A$1:$C$39,3,0) -> CABO | F18: =S18 -> 0 | S18: =SUM(G18:R18) -> 0 | V18: =V17+1 -> 13 | W18: =D18 -> 5.TRUYỀN THỐNG | X18: =E18 -> CABO | Y18: =X42 -> VỌT HOA XOÀI
C19: =C18+1 -> 14 | D19: =VLOOKUP(C19,DMSP!$A$1:$C$39,2,0) -> 5.TRUYỀN THỐNG | E19: =VLOOKUP(C19,DMSP!$A$1:$C$39,3,0) -> F94 | F19: =S19 -> 0 | S19: =SUM(G19:R19) -> 0 | V19: =V18+1 -> 14 | W19: =D19 -> 5.TRUYỀN THỐNG | X19: =E19 -> F94 | Y19: SẢN PHẨM | Z19: SẢN PHẨM | AA19: SẢN PHẨM | AB19: SẢN PHẨM | AC19: SẢN PHẨM | AD19: SẢN PHẨM
C20: =C19+1 -> 15 | D20: =VLOOKUP(C20,DMSP!$A$1:$C$39,2,0) -> 5.TRUYỀN THỐNG | E20: =VLOOKUP(C20,DMSP!$A$1:$C$39,3,0) -> F95 | F20: =S20 -> 0 | S20: =SUM(G20:R20) -> 0 | V20: =V19+1 -> 15 | W20: =D20 -> 5.TRUYỀN THỐNG | X20: =E20 -> F95
C21: =C20+1 -> 16 | D21: =VLOOKUP(C21,DMSP!$A$1:$C$39,2,0) -> 5.TRUYỀN THỐNG | E21: =VLOOKUP(C21,DMSP!$A$1:$C$39,3,0) -> THIOURE | F21: =S21 -> 0 | S21: =SUM(G21:R21) -> 0 | V21: =V20+1 -> 16 | W21: =D21 -> 5.TRUYỀN THỐNG | X21: =E21 -> THIOURE | Y21: SẢN PHẨM | Z21: SẢN PHẨM | AA21: SẢN PHẨM | AB21: SẢN PHẨM | AC21: SẢN PHẨM | AD21: SẢN PHẨM
C22: =C21+1 -> 17 | D22: =VLOOKUP(C22,DMSP!$A$1:$C$39,2,0) -> 5.TRUYỀN THỐNG | E22: =VLOOKUP(C22,DMSP!$A$1:$C$39,3,0) -> TOBA JUM | F22: =S22 -> 0 | S22: =SUM(G22:R22) -> 0 | V22: =V21+1 -> 17 | W22: =D22 -> 5.TRUYỀN THỐNG | X22: =E22 -> TOBA JUM
C23: =C22+1 -> 18 | D23: =VLOOKUP(C23,DMSP!$A$1:$C$39,2,0) -> 5.TRUYỀN THỐNG | E23: =VLOOKUP(C23,DMSP!$A$1:$C$39,3,0) -> TOBA NET | F23: =S23 -> 0 | S23: =SUM(G23:R23) -> 0 | V23: =V22+1 -> 18 | W23: =D23 -> 5.TRUYỀN THỐNG | X23: =E23 -> TOBA NET | Z23: =DSUM($E$5:$T$2133,"1",$Y$9:$Y$10) -> 90
C24: =C23+1 -> 19 | D24: =VLOOKUP(C24,DMSP!$A$1:$C$39,2,0) -> 6.BVTV | E24: =VLOOKUP(C24,DMSP!$A$1:$C$39,3,0) -> ABAFAX 1.8 | F24: =S24 -> 0 | S24: =SUM(G24:R24) -> 0 | V24: =V23+1 -> 19 | W24: =D24 -> 6.BVTV | X24: =E24 -> ABAFAX 1.8
C25: =C24+1 -> 20 | D25: =VLOOKUP(C25,DMSP!$A$1:$C$39,2,0) -> 6.BVTV | E25: =VLOOKUP(C25,DMSP!$A$1:$C$39,3,0) -> ABAFAX 3.6 | F25: =S25 -> 0 | S25: =SUM(G25:R25) -> 0 | V25: =V24+1 -> 20 | W25: =D25 -> 6.BVTV | X25: =E25 -> ABAFAX 3.6
C26: =C25+1 -> 21 | D26: =VLOOKUP(C26,DMSP!$A$1:$C$39,2,0) -> 6.BVTV | E26: =VLOOKUP(C26,DMSP!$A$1:$C$39,3,0) -> AZET | F26: =S26 -> 0 | S26: =SUM(G26:R26) -> 0 | V26: =V25+1 -> 21 | W26: =D26 -> 6.BVTV | X26: =E26 -> AZET
C27: =C26+1 -> 22 | D27: =VLOOKUP(C27,DMSP!$A$1:$C$39,2,0) -> 6.BVTV | E27: =VLOOKUP(C27,DMSP!$A$1:$C$39,3,0) -> BACBA | F27: =S27 -> 0 | S27: =SUM(G27:R27) -> 0 | V27: =V26+1 -> 22 | W27: =D27 -> 6.BVTV | X27: =E27 -> BACBA
C28: =C27+1 -> 23 | D28: =VLOOKUP(C28,DMSP!$A$1:$C$39,2,0) -> 6.BVTV | E28: =VLOOKUP(C28,DMSP!$A$1:$C$39,3,0) -> BIOROSAMIL | F28: =S28 -> 10 | G28: 10 | S28: =SUM(G28:R28) -> 10 | V28: =V27+1 -> 23 | W28: =D28 -> 6.BVTV | X28: =E28 -> BIOROSAMIL
C29: =C28+1 -> 24 | D29: =VLOOKUP(C29,DMSP!$A$1:$C$39,2,0) -> 6.BVTV | E29: =VLOOKUP(C29,DMSP!$A$1:$C$39,3,0) -> COC 86 | F29: =S29 -> 0 | S29: =SUM(G29:R29) -> 0 | V29: =V28+1 -> 24 | W29: =D29 -> 6.BVTV | X29: =E29 -> COC 86
C30: =C29+1 -> 25 | D30: =VLOOKUP(C30,DMSP!$A$1:$C$39,2,0) -> 6.BVTV | E30: =VLOOKUP(C30,DMSP!$A$1:$C$39,3,0) -> HEXA 5 | F30: =S30 -> 75 | G30: 15 | H30: 15 | J30: 30 | L30: 15 | S30: =SUM(G30:R30) -> 75 | V30: =V29+1 -> 25 | W30: =D30 -> 6.BVTV | X30: =E30 -> HEXA 5
C31: =C30+1 -> 26 | D31: =VLOOKUP(C31,DMSP!$A$1:$C$39,2,0) -> 6.BVTV | E31: =VLOOKUP(C31,DMSP!$A$1:$C$39,3,0) -> TAMALA | F31: =S31 -> 0 | S31: =SUM(G31:R31) -> 0 | V31: =V30+1 -> 26 | W31: =D31 -> 6.BVTV | X31: =E31 -> TAMALA
C32: =C31+1 -> 27 | D32: =VLOOKUP(C32,DMSP!$A$1:$C$39,2,0) -> 7.KHÁC | E32: =VLOOKUP(C32,DMSP!$A$1:$C$39,3,0) -> KẼM VÀNG | F32: =S32 -> 0 | S32: =SUM(G32:R32) -> 0 | V32: =V31+1 -> 27 | W32: =D32 -> 7.KHÁC | X32: =E32 -> KẼM VÀNG
C33: =C32+1 -> 28 | D33: =VLOOKUP(C33,DMSP!$A$1:$C$39,2,0) -> 7.KHÁC | E33: =VLOOKUP(C33,DMSP!$A$1:$C$39,3,0) -> KHÁC1 | F33: =S33 -> 56 | G33: 5 | I33: 13 | J33: 14 | Q33: 24 | S33: =SUM(G33:R33) -> 56 | V33: =V32+1 -> 28 | W33: =D33 -> 7.KHÁC | X33: =E33 -> KHÁC1
C34: =C33+1 -> 29 | D34: =VLOOKUP(C34,DMSP!$A$1:$C$39,2,0) -> 7.KHÁC | E34: REACH | F34: =S34 -> 38 | G34: 19 | H34: 19 | S34: =SUM(G34:R34) -> 38 | V34: =V33+1 -> 29 | W34: =D34 -> 7.KHÁC | X34: =E34 -> REACH
C35: =C34+1 -> 30 | D35: =VLOOKUP(C35,DMSP!$A$1:$C$39,2,0) -> 7.KHÁC | E35: =VLOOKUP(C35,DMSP!$A$1:$C$39,3,0) -> RỬA RONG RÊU | F35: =S35 -> 0 | S35: =SUM(G35:R35) -> 0 | V35: =V34+1 -> 30 | W35: =D35 -> 7.KHÁC | X35: =E35 -> RỬA RONG RÊU
C36: =C35+1 -> 31 | D36: =VLOOKUP(C36,DMSP!$A$1:$C$39,2,0) -> 7.KHÁC | E36: =VLOOKUP(C36,DMSP!$A$1:$C$39,3,0) -> TB BO | F36: =S36 -> 0 | S36: =SUM(G36:R36) -> 0 | V36: =V35+1 -> 31 | W36: =D36 -> 7.KHÁC | X36: =E36 -> TB BO
C37: =C36+1 -> 32 | D37: =VLOOKUP(C37,DMSP!$A$1:$C$39,2,0) -> 7.KHÁC | E37: =VLOOKUP(C37,DMSP!$A$1:$C$39,3,0) -> TB FRUIT | F37: =S37 -> 0 | S37: =SUM(G37:R37) -> 0 | V37: =V36+1 -> 32 | W37: =D37 -> 7.KHÁC | X37: =E37 -> TB FRUIT
C38: =C37+1 -> 33 | D38: =VLOOKUP(C38,DMSP!$A$1:$C$39,2,0) -> 7.KHÁC | E38: =VLOOKUP(C38,DMSP!$A$1:$C$39,3,0) -> TB PHOS | F38: =S38 -> 0 | S38: =SUM(G38:R38) -> 0 | V38: =V37+1 -> 33 | W38: =D38 -> 7.KHÁC | X38: =E38 -> TB PHOS
C39: =C38+1 -> 34 | D39: =VLOOKUP(C39,DMSP!$A$1:$C$39,2,0) -> 7.KHÁC | E39: =VLOOKUP(C39,DMSP!$A$1:$C$39,3,0) -> TOBA BÁM DÍNH | F39: =S39 -> 4 | H39: 4 | S39: =SUM(G39:R39) -> 4 | V39: =V38+1 -> 34 | W39: =D39 -> 7.KHÁC | X39: =E39 -> TOBA BÁM DÍNH
C40: =C39+1 -> 35 | D40: =VLOOKUP(C40,DMSP!$A$1:$C$39,2,0) -> 7.KHÁC | E40: =VLOOKUP(C40,DMSP!$A$1:$C$39,3,0) -> VỌT HOA NHÃN | F40: =S40 -> 0 | S40: =SUM(G40:R40) -> 0 | V40: =V39+1 -> 35 | W40: =D40 -> 7.KHÁC | X40: =E40 -> VỌT HOA NHÃN
C41: =C40+1 -> 36 | D41: =VLOOKUP(C41,DMSP!$A$1:$C$39,2,0) -> 7.KHÁC | E41: =VLOOKUP(C41,DMSP!$A$1:$C$39,3,0) -> VỌT HOA XOÀI | F41: =S41 -> 0 | S41: =SUM(G41:R41) -> 0 | V41: =V40+1 -> 36 | W41: =D41 -> 7.KHÁC | X41: =E41 -> VỌT HOA XOÀI
...

Sheet SL TỔNG THEO SẢN PHẨM
A1: =R40 -> 90431 | E1: TRIỆU Đồng | F1: KẾ HOẠCH DOANH SỐ THEO SẢN PHẨM NĂM 2020 VÙNG..................... | W1: 1 | X1: 2 | Y1: =X1+1 -> 3 | Z1: =Y1+1 -> 4 | AA1: =Z1+1 -> 5 | AB1: =AA1+1 -> 6 | AC1: =AB1+1 -> 7 | AD1: =AC1+1 -> 8 | AE1: =AD1+1 -> 9 | AF1: =AE1+1 -> 10 | ... AH1: =AG1+1 -> 12
A2: TÊN KH | B2: TT | C2: NHÓM SP | D2: SẢN PHẨM | E2: TỔNG | F2: 1 | G2: 2 | H2: 3 | I2: 4 | J2: 5 | K2: 6 | L2: 7 | M2: 8 | N2: 9 | O2: 10 | P2: 11 | Q2: 12 | R2: Grand Total | T2: CỘT | U2: TỪ | V2: ĐẾN | AI2: 1 | AJ2: =AI2+1 -> 2 | AK2: =AJ2+1 -> 3 | AL2: =AK2+1 -> 4 | AM2: =AL2+1 -> 5 | AN2: =AM2+1 -> 6 | AO2: =AN2+1 -> 7 | AP2: =AO2+1 -> 8 | AQ2: =AP2+1 -> 9 | ... AT2: =AS2+1 -> 12 | AY2: 1 | AZ2: =AY2+1 -> 2 | BA2: =AZ2+1 -> 3 | BB2: =BA2+1 -> 4 | BC2: =BB2+1 -> 5 | BD2: =BC2+1 -> 6 | BE2: =BD2+1 -> 7 | BF2: =BE2+1 -> 8 | BG2: =BF2+1 -> 9 | ... BJ2: =BI2+1 -> 12
A3: ĐL 1234 | B3: 1 | C3: =VLOOKUP(B3,DMSP!$A$1:$C$39,2,0) -> 1.TOBA XANH | D3: =VLOOKUP(B3,DMSP!$A$1:$C$39,3,0) -> TOBA XANH | E3: =R3 -> 7 | F3: =DSUM('KHACH HANG'!$E$5:$R$2133,"1",'KHACH HANG'!$Y$5:$Y$6) -> 0 | G3: =DSUM('KHACH HANG'!$E$5:$R$2133,"2",'KHACH HANG'!$Y$5:$Y$6) -> 7 | H3: =DSUM('KHACH HANG'!$E$5:$R$2133,"3",'KHACH HANG'!$Y$5:$Y$6) -> 0 | I3: =DSUM('KHACH HANG'!$E$5:$R$2133,"4",'KHACH HANG'!$Y$5:$Y$6) -> 0 | J3: =DSUM('KHACH HANG'!$E$5:$R$2133,"5",'KHACH HANG'!$Y$5:$Y$6) -> 0 | K3: =DSUM('KHACH HANG'!$E$5:$R$2133,"6",'KHACH HANG'!$Y$5:$Y$6) -> 0 | L3: =DSUM('KHACH HANG'!$E$5:$R$2133,"7",'KHACH HANG'!$Y$5:$Y$6) -> 0 | M3: =DSUM('KHACH HANG'!$E$5:$R$2133,"8",'KHACH HANG'!$Y$5:$Y$6) -> 0 | N3: =DSUM('KHACH HANG'!$E$5:$R$2133,"9",'KHACH HANG'!$Y$5:$Y$6) -> 0 | O3: =DSUM('KHACH HANG'!$E$5:$R$2133,"10",'KHACH HANG'!$Y$5:$Y$6) -> 0 | P3: =DSUM('KHACH HANG'!$E$5:$R$2133,"11",'KHACH HANG'!$Y$5:$Y$6) -> 0 | Q3: =DSUM('KHACH HANG'!$E$5:$R$2133,"12",'KHACH HANG'!$Y$5:$Y$6) -> 0 | R3: =SUM(F3:Q3) -> 7 | T3: X | U3: 5 | V3: 6 | W3: DSUM('NHAN VIEN'!$E$5:$Q$2133,"1" | X3: ="DSUM('NHAN VIEN'!$E$5:$Q$2133,"&""""&$X$1&"""" -> DSUM('NHAN VIEN'!$E$5:$Q$2133,"2" | Y3: ="DSUM('NHAN VIEN'!$E$5:$Q$2133,"&""""&$Y$1&"""" -> DSUM('NHAN VIEN'!$E$5:$Q$2133,"3" | Z3: ="DSUM('NHAN VIEN'!$E$5:$Q$2133,"&""""&$Z$1&"""" -> DSUM('NHAN VIEN'!$E$5:$Q$2133,"4" | AA3: ="DSUM('NHAN VIEN'!$E$5:$Q$2133,"&""""&$AA$1&"""" -> DSUM('NHAN VIEN'!$E$5:$Q$2133,"5" | AB3: ="DSUM('NHAN VIEN'!$E$5:$Q$2133,"&""""&$AB$1&"""" -> DSUM('NHAN VIEN'!$E$5:$Q$2133,"6" | AC3: ="DSUM('NHAN VIEN'!$E$5:$Q$2133,"&""""&$AC$1&"""" -> DSUM('NHAN VIEN'!$E$5:$Q$2133,"7" | AD3: ="DSUM('NHAN VIEN'!$E$5:$Q$2133,"&""""&$AD$1&"""" -> DSUM('NHAN VIEN'!$E$5:$Q$2133,"8" | AE3: ="DSUM('NHAN VIEN'!$E$5:$Q$2133,"&""""&$AE$1&"""" -> DSUM('NHAN VIEN'!$E$5:$Q$2133,"9" | AF3: ="DSUM('NHAN VIEN'!$E$5:$Q$2133,"&""""&$AF$1&"""" -> DSUM('NHAN VIEN'!$E$5:$Q$2133,"10" | AG3: ="DSUM('NHAN VIEN'!$E$5:$Q$2133,"&""""&$AG$1&"""" -> DSUM('NHAN VIEN'!$E$5:$Q$2133,"11" | AH3: ="DSUM('NHAN VIEN'!$E$5:$Q$2133,"&""""&$AH$1&"""" -> DSUM('NHAN VIEN'!$E$5:$Q$2133,"12" | AI3: =W3&","&AV3&")" -> DSUM('NHAN VIEN'!$E$5:$Q$2133,"1",'NHAN VIEN'!$X$5:$X$6) | AJ3: =X3&","&AV3&")" -> DSUM('NHAN VIEN'!$E$5:$Q$2133,"2",'NHAN VIEN'!$X$5:$X$6) | AK3: =Y3&","&AV3&")" -> DSUM('NHAN VIEN'!$E$5:$Q$2133,"3",'NHAN VIEN'!$X$5:$X$6) | AL3: =Z3&","&AV3&")" -> DSUM('NHAN VIEN'!$E$5:$Q$2133,"4",'NHAN VIEN'!$X$5:$X$6) | AM3: =AA3&","&AV3&")" -> DSUM('NHAN VIEN'!$E$5:$Q$2133,"5",'NHAN VIEN'!$X$5:$X$6) | AN3: =AB3&","&AV3&")" -> DSUM('NHAN VIEN'!$E$5:$Q$2133,"6",'NHAN VIEN'!$X$5:$X$6) | AO3: =AC3&","&AV3&")" -> DSUM('NHAN VIEN'!$E$5:$Q$2133,"7",'NHAN VIEN'!$X$5:$X$6) | AP3: =AD3&","&AV3&")" -> DSUM('NHAN VIEN'!$E$5:$Q$2133,"8",'NHAN VIEN'!$X$5:$X$6) | AQ3: =AE3&","&AV3&")" -> DSUM('NHAN VIEN'!$E$5:$Q$2133,"9",'NHAN VIEN'!$X$5:$X$6) | AR3: =AF3&","&AV3&")" -> DSUM('NHAN VIEN'!$E$5:$Q$2133,"10",'NHAN VIEN'!$X$5:$X$6) | AS3: =AG3&","&AV3&")" -> DSUM('NHAN VIEN'!$E$5:$Q$2133,"11",'NHAN VIEN'!$X$5:$X$6) | AT3: =AH3&","&AV3&")" -> DSUM('NHAN VIEN'!$E$5:$Q$2133,"12",'NHAN VIEN'!$X$5:$X$6) | AU3: =AI3&","&$AV$3&")" -> DSUM('NHAN VIEN'!$E$5:$Q$2133,"1",'NHAN VIEN'!$X$5:$X$6),'NHAN VIEN'!$X$5:$X$6) | AV3: ="'NHAN VIEN'!$"&T3&"$"&U3&":$"&T3&"$"&V3 -> 'NHAN VIEN'!$X$5:$X$6 | AY3: ="="&AI3 -> =DSUM('NHAN VIEN'!$E$5:$Q$2133,"1",'NHAN VIEN'!$X$5:$X$6) | AZ3: ="="&AJ3 -> =DSUM('NHAN VIEN'!$E$5:$Q$2133,"2",'NHAN VIEN'!$X$5:$X$6) | BA3: ="="&AK3 -> =DSUM('NHAN VIEN'!$E$5:$Q$2133,"3",'NHAN VIEN'!$X$5:$X$6) | BB3: ="="&AL3 -> =DSUM('NHAN VIEN'!$E$5:$Q$2133,"4",'NHAN VIEN'!$X$5:$X$6) | BC3: ="="&AM3 -> =DSUM('NHAN VIEN'!$E$5:$Q$2133,"5",'NHAN VIEN'!$X$5:$X$6) | BD3: ="="&AN3 -> =DSUM('NHAN VIEN'!$E$5:$Q$2133,"6",'NHAN VIEN'!$X$5:$X$6) | BE3: ="="&AO3 -> =DSUM('NHAN VIEN'!$E$5:$Q$2133,"7",'NHAN VIEN'!$X$5:$X$6) | BF3: ="="&AP3 -> =DSUM('NHAN VIEN'!$E$5:$Q$2133,"8",'NHAN VIEN'!$X$5:$X$6) | ... BJ3: ="="&AT3 -> =DSUM('NHAN VIEN'!$E$5:$Q$2133,"12",'NHAN VIEN'!$X$5:$X$6) | BR3: =R3-'KHACH HANG'!S6 -> 7
B4: =B3+1 -> 2 | C4: =VLOOKUP(B4,DMSP!$A$1:$C$39,2,0) -> 2.HC | D4: =VLOOKUP(B4,DMSP!$A$1:$C$39,3,0) -> HC BOOSTER | E4: =R4 -> 167 | F4: =DSUM('KHACH HANG'!$E$5:$R$2133,"1",'KHACH HANG'!$Z$5:$Z$6) -> 72 | G4: =DSUM('KHACH HANG'!$E$5:$R$2133,"2",'KHACH HANG'!$Z$5:$Z$6) -> 0 | H4: =DSUM('KHACH HANG'!$E$5:$R$2133,"3",'KHACH HANG'!$Z$5:$Z$6) -> 0 | I4: =DSUM('KHACH HANG'!$E$5:$R$2133,"4",'KHACH HANG'!$Z$5:$Z$6) -> 55 | J4: =DSUM('KHACH HANG'!$E$5:$R$2133,"5",'KHACH HANG'!$Z$5:$Z$6) -> 0 | K4: =DSUM('KHACH HANG'!$E$5:$R$2133,"6",'KHACH HANG'!$Z$5:$Z$6) -> 0 | L4: =DSUM('KHACH HANG'!$E$5:$R$2133,"7",'KHACH HANG'!$Z$5:$Z$6) -> 0 | M4: =DSUM('KHACH HANG'!$E$5:$R$2133,"8",'KHACH HANG'!$Z$5:$Z$6) -> 0 | N4: =DSUM('KHACH HANG'!$E$5:$R$2133,"9",'KHACH HANG'!$Z$5:$Z$6) -> 0 | O4: =DSUM('KHACH HANG'!$E$5:$R$2133,"10",'KHACH HANG'!$Z$5:$Z$6) -> 40 | P4: =DSUM('KHACH HANG'!$E$5:$R$2133,"11",'KHACH HANG'!$Z$5:$Z$6) -> 0 | Q4: =DSUM('KHACH HANG'!$E$5:$R$2133,"12",'KHACH HANG'!$Z$5:$Z$6) -> 0 | R4: =SUM(F4:Q4) -> 167 | T4: Y | U4: 5 | V4: 6 | W4: DSUM('NHAN VIEN'!$E$5:$Q$2133,"1" | X4: ="DSUM('NHAN VIEN'!$E$5:$Q$2133,"&""""&$X$1&"""" -> DSUM('NHAN VIEN'!$E$5:$Q$2133,"2" | Y4: ="DSUM('NHAN VIEN'!$E$5:$Q$2133,"&""""&$Y$1&"""" -> DSUM('NHAN VIEN'!$E$5:$Q$2133,"3" | Z4: ="DSUM('NHAN VIEN'!$E$5:$Q$2133,"&""""&$Z$1&"""" -> DSUM('NHAN VIEN'!$E$5:$Q$2133,"4" | AA4: ="DSUM('NHAN VIEN'!$E$5:$Q$2133,"&""""&$AA$1&"""" -> DSUM('NHAN VIEN'!$E$5:$Q$2133,"5" | AB4: ="DSUM('NHAN VIEN'!$E$5:$Q$2133,"&""""&$AB$1&"""" -> DSUM('NHAN VIEN'!$E$5:$Q$2133,"6" | AC4: ="DSUM('NHAN VIEN'!$E$5:$Q$2133,"&""""&$AC$1&"""" -> DSUM('NHAN VIEN'!$E$5:$Q$2133,"7" | AD4: ="DSUM('NHAN VIEN'!$E$5:$Q$2133,"&""""&$AD$1&"""" -> DSUM('NHAN VIEN'!$E$5:$Q$2133,"8" | AE4: ="DSUM('NHAN VIEN'!$E$5:$Q$2133,"&""""&$AE$1&"""" -> DSUM('NHAN VIEN'!$E$5:$Q$2133,"9" | AF4: ="DSUM('NHAN VIEN'!$E$5:$Q$2133,"&""""&$AF$1&"""" -> DSUM('NHAN VIEN'!$E$5:$Q$2133,"10" | AG4: ="DSUM('NHAN VIEN'!$E$5:$Q$2133,"&""""&$AG$1&"""" -> DSUM('NHAN VIEN'!$E$5:$Q$2133,"11" | AH4: ="DSUM('NHAN VIEN'!$E$5:$Q$2133,"&""""&$AH$1&"""" -> DSUM('NHAN VIEN'!$E$5:$Q$2133,"12" | AI4: =W4&","&AV4&")" -> DSUM('NHAN VIEN'!$E$5:$Q$2133,"1",'NHAN VIEN'!$Y$5:$Y$6) | AJ4: =X4&","&AV4&")" -> DSUM('NHAN VIEN'!$E$5:$Q$2133,"2",'NHAN VIEN'!$Y$5:$Y$6) | AK4: =Y4&","&AV4&")" -> DSUM('NHAN VIEN'!$E$5:$Q$2133,"3",'NHAN VIEN'!$Y$5:$Y$6) | AL4: =Z4&","&AV4&")" -> DSUM('NHAN VIEN'!$E$5:$Q$2133,"4",'NHAN VIEN'!$Y$5:$Y$6) | AM4: =AA4&","&AV4&")" -> DSUM('NHAN VIEN'!$E$5:$Q$2133,"5",'NHAN VIEN'!$Y$5:$Y$6) | AN4: =AB4&","&AV4&")" -> DSUM('NHAN VIEN'!$E$5:$Q$2133,"6",'NHAN VIEN'!$Y$5:$Y$6) | AO4: =AC4&","&AV4&")" -> DSUM('NHAN VIEN'!$E$5:$Q$2133,"7",'NHAN VIEN'!$Y$5:$Y$6) | AP4: =AD4&","&AV4&")" -> DSUM('NHAN VIEN'!$E$5:$Q$2133,"8",'NHAN VIEN'!$Y$5:$Y$6) | AQ4: =AE4&","&AV4&")" -> DSUM('NHAN VIEN'!$E$5:$Q$2133,"9",'NHAN VIEN'!$Y$5:$Y$6) | AR4: =AF4&","&AV4&")" -> DSUM('NHAN VIEN'!$E$5:$Q$2133,"10",'NHAN VIEN'!$Y$5:$Y$6) | AS4: =AG4&","&AV4&")" -> DSUM('NHAN VIEN'!$E$5:$Q$2133,"11",'NHAN VIEN'!$Y$5:$Y$6) | AT4: =AH4&","&AV4&")" -> DSUM('NHAN VIEN'!$E$5:$Q$2133,"12",'NHAN VIEN'!$Y$5:$Y$6) | AV4: ="'NHAN VIEN'!$"&T4&"$"&U4&":$"&T4&"$"&V4 -> 'NHAN VIEN'!$Y$5:$Y$6 | AY4: ="="&AI4 -> =DSUM('NHAN VIEN'!$E$5:$Q$2133,"1",'NHAN VIEN'!$Y$5:$Y$6) | AZ4: ="="&AJ4 -> =DSUM('NHAN VIEN'!$E$5:$Q$2133,"2",'NHAN VIEN'!$Y$5:$Y$6) | BA4: ="="&AK4 -> =DSUM('NHAN VIEN'!$E$5:$Q$2133,"3",'NHAN VIEN'!$Y$5:$Y$6) | BB4: ="="&AL4 -> =DSUM('NHAN VIEN'!$E$5:$Q$2133,"4",'NHAN VIEN'!$Y$5:$Y$6) | BC4: ="="&AM4 -> =DSUM('NHAN VIEN'!$E$5:$Q$2133,"5",'NHAN VIEN'!$Y$5:$Y$6) | BD4: ="="&AN4 -> =DSUM('NHAN VIEN'!$E$5:$Q$2133,"6",'NHAN VIEN'!$Y$5:$Y$6) | BE4: ="="&AO4 -> =DSUM('NHAN VIEN'!$E$5:$Q$2133,"7",'NHAN VIEN'!$Y$5:$Y$6) | BF4: ="="&AP4 -> =DSUM('NHAN VIEN'!$E$5:$Q$2133,"8",'NHAN VIEN'!$Y$5:$Y$6) | ... BJ4: ="="&AT4 -> =DSUM('NHAN VIEN'!$E$5:$Q$2133,"12",'NHAN VIEN'!$Y$5:$Y$6) | BR4: =R4-'KHACH HANG'!S7 -> 156
B5: =B4+1 -> 3 | C5: =VLOOKUP(B5,DMSP!$A$1:$C$39,2,0) -> 2.HC | D5: =VLOOKUP(B5,DMSP!$A$1:$C$39,3,0) -> HC KING-ROOT | E5: =R5 -> 19 | F5: =DSUM('KHACH HANG'!$E$5:$R$2133,"1",'KHACH HANG'!$AA$5:$AA$6) -> 0 | G5: =DSUM('KHACH HANG'!$E$5:$R$2133,"2",'KHACH HANG'!$AA$5:$AA$6) -> 0 | H5: =DSUM('KHACH HANG'!$E$5:$R$2133,"3",'KHACH HANG'!$AA$5:$AA$6) -> 12 | I5: =DSUM('KHACH HANG'!$E$5:$R$2133,"4",'KHACH HANG'!$AA$5:$AA$6) -> 0 | J5: =DSUM('KHACH HANG'!$E$5:$R$2133,"5",'KHACH HANG'!$AA$5:$AA$6) -> 2 | K5: =DSUM('KHACH HANG'!$E$5:$R$2133,"6",'KHACH HANG'!$AA$5:$AA$6) -> 0 | L5: =DSUM('KHACH HANG'!$E$5:$R$2133,"7",'KHACH HANG'!$AA$5:$AA$6) -> 0 | M5: =DSUM('KHACH HANG'!$E$5:$R$2133,"8",'KHACH HANG'!$AA$5:$AA$6) -> 0 | N5: =DSUM('KHACH HANG'!$E$5:$R$2133,"9",'KHACH HANG'!$AA$5:$AA$6) -> 0 | O5: =DSUM('KHACH HANG'!$E$5:$R$2133,"10",'KHACH HANG'!$AA$5:$AA$6) -> 0 | P5: =DSUM('KHACH HANG'!$E$5:$R$2133,"11",'KHACH HANG'!$AA$5:$AA$6) -> 0 | Q5: =DSUM('KHACH HANG'!$E$5:$R$2133,"12",'KHACH HANG'!$AA$5:$AA$6) -> 5 | R5: =SUM(F5:Q5) -> 19 | T5: Z | U5: 5 | V5: 6 | W5: DSUM('NHAN VIEN'!$E$5:$Q$2133,"1" | X5: ="DSUM('NHAN VIEN'!$E$5:$Q$2133,"&""""&$X$1&"""" -> DSUM('NHAN VIEN'!$E$5:$Q$2133,"2" | Y5: ="DSUM('NHAN VIEN'!$E$5:$Q$2133,"&""""&$Y$1&"""" -> DSUM('NHAN VIEN'!$E$5:$Q$2133,"3" | Z5: ="DSUM('NHAN VIEN'!$E$5:$Q$2133,"&""""&$Z$1&"""" -> DSUM('NHAN VIEN'!$E$5:$Q$2133,"4" | AA5: ="DSUM('NHAN VIEN'!$E$5:$Q$2133,"&""""&$AA$1&"""" -> DSUM('NHAN VIEN'!$E$5:$Q$2133,"5" | AB5: ="DSUM('NHAN VIEN'!$E$5:$Q$2133,"&""""&$AB$1&"""" -> DSUM('NHAN VIEN'!$E$5:$Q$2133,"6" | AC5: ="DSUM('NHAN VIEN'!$E$5:$Q$2133,"&""""&$AC$1&"""" -> DSUM('NHAN VIEN'!$E$5:$Q$2133,"7" | AD5: ="DSUM('NHAN VIEN'!$E$5:$Q$2133,"&""""&$AD$1&"""" -> DSUM('NHAN VIEN'!$E$5:$Q$2133,"8" | AE5: ="DSUM('NHAN VIEN'!$E$5:$Q$2133,"&""""&$AE$1&"""" -> DSUM('NHAN VIEN'!$E$5:$Q$2133,"9" | AF5: ="DSUM('NHAN VIEN'!$E$5:$Q$2133,"&""""&$AF$1&"""" -> DSUM('NHAN VIEN'!$E$5:$Q$2133,"10" | AG5: ="DSUM('NHAN VIEN'!$E$5:$Q$2133,"&""""&$AG$1&"""" -> DSUM('NHAN VIEN'!$E$5:$Q$2133,"11" | AH5: ="DSUM('NHAN VIEN'!$E$5:$Q$2133,"&""""&$AH$1&"""" -> DSUM('NHAN VIEN'!$E$5:$Q$2133,"12" | AI5: =W5&","&AV5&")" -> DSUM('NHAN VIEN'!$E$5:$Q$2133,"1",'NHAN VIEN'!$Z$5:$Z$6) | AJ5: =X5&","&AV5&")" -> DSUM('NHAN VIEN'!$E$5:$Q$2133,"2",'NHAN VIEN'!$Z$5:$Z$6) | AK5: =Y5&","&AV5&")" -> DSUM('NHAN VIEN'!$E$5:$Q$2133,"3",'NHAN VIEN'!$Z$5:$Z$6) | AL5: =Z5&","&AV5&")" -> DSUM('NHAN VIEN'!$E$5:$Q$2133,"4",'NHAN VIEN'!$Z$5:$Z$6) | AM5: =AA5&","&AV5&")" -> DSUM('NHAN VIEN'!$E$5:$Q$2133,"5",'NHAN VIEN'!$Z$5:$Z$6) | AN5: =AB5&","&AV5&")" -> DSUM('NHAN VIEN'!$E$5:$Q$2133,"6",'NHAN VIEN'!$Z$5:$Z$6) | AO5: =AC5&","&AV5&")" -> DSUM('NHAN VIEN'!$E$5:$Q$2133,"7",'NHAN VIEN'!$Z$5:$Z$6) | AP5: =AD5&","&AV5&")" -> DSUM('NHAN VIEN'!$E$5:$Q$2133,"8",'NHAN VIEN'!$Z$5:$Z$6) | AQ5: =AE5&","&AV5&")" -> DSUM('NHAN VIEN'!$E$5:$Q$2133,"9",'NHAN VIEN'!$Z$5:$Z$6) | AR5: =AF5&","&AV5&")" -> DSUM('NHAN VIEN'!$E$5:$Q$2133,"10",'NHAN VIEN'!$Z$5:$Z$6) | AS5: =AG5&","&AV5&")" -> DSUM('NHAN VIEN'!$E$5:$Q$2133,"11",'NHAN VIEN'!$Z$5:$Z$6) | AT5: =AH5&","&AV5&")" -> DSUM('NHAN VIEN'!$E$5:$Q$2133,"12",'NHAN VIEN'!$Z$5:$Z$6) | AV5: ="'NHAN VIEN'!$"&T5&"$"&U5&":$"&T5&"$"&V5 -> 'NHAN VIEN'!$Z$5:$Z$6 | AY5: ="="&AI5 -> =DSUM('NHAN VIEN'!$E$5:$Q$2133,"1",'NHAN VIEN'!$Z$5:$Z$6) | AZ5: ="="&AJ5 -> =DSUM('NHAN VIEN'!$E$5:$Q$2133,"2",'NHAN VIEN'!$Z$5:$Z$6) | BA5: ="="&AK5 -> =DSUM('NHAN VIEN'!$E$5:$Q$2133,"3",'NHAN VIEN'!$Z$5:$Z$6) | BB5: ="="&AL5 -> =DSUM('NHAN VIEN'!$E$5:$Q$2133,"4",'NHAN VIEN'!$Z$5:$Z$6) | BC5: ="="&AM5 -> =DSUM('NHAN VIEN'!$E$5:$Q$2133,"5",'NHAN VIEN'!$Z$5:$Z$6) | BD5: ="="&AN5 -> =DSUM('NHAN VIEN'!$E$5:$Q$2133,"6",'NHAN VIEN'!$Z$5:$Z$6) | BE5: ="="&AO5 -> =DSUM('NHAN VIEN'!$E$5:$Q$2133,"7",'NHAN VIEN'!$Z$5:$Z$6) | BF5: ="="&AP5 -> =DSUM('NHAN VIEN'!$E$5:$Q$2133,"8",'NHAN VIEN'!$Z$5:$Z$6) | ... BJ5: ="="&AT5 -> =DSUM('NHAN VIEN'!$E$5:$Q$2133,"12",'NHAN VIEN'!$Z$5:$Z$6) | BR5: =R5-'KHACH HANG'!S8 -> 19
B6: =B5+1 -> 4 | C6: =VLOOKUP(B6,DMSP!$A$1:$C$39,2,0) -> 2.HC | D6: =VLOOKUP(B6,DMSP!$A$1:$C$39,3,0) -> HAPPY FARM | E6: =R6 -> 41 | F6: =DSUM('KHACH HANG'!$E$5:$R$2133,"1",'KHACH HANG'!$AB$5:$AB$6) -> 41 | G6: =DSUM('KHACH HANG'!$E$5:$R$2133,"2",'KHACH HANG'!$AB$5:$AB$6) -> 0 | H6: =DSUM('KHACH HANG'!$E$5:$R$2133,"3",'KHACH HANG'!$AB$5:$AB$6) -> 0 | I6: =DSUM('KHACH HANG'!$E$5:$R$2133,"4",'KHACH HANG'!$AB$5:$AB$6) -> 0 | J6: =DSUM('KHACH HANG'!$E$5:$R$2133,"5",'KHACH HANG'!$AB$5:$AB$6) -> 0 | K6: =DSUM('KHACH HANG'!$E$5:$R$2133,"6",'KHACH HANG'!$AB$5:$AB$6) -> 0 | L6: =DSUM('KHACH HANG'!$E$5:$R$2133,"7",'KHACH HANG'!$AB$5:$AB$6) -> 0 | M6: =DSUM('KHACH HANG'!$E$5:$R$2133,"8",'KHACH HANG'!$AB$5:$AB$6) -> 0 | N6: =DSUM('KHACH HANG'!$E$5:$R$2133,"9",'KHACH HANG'!$AB$5:$AB$6) -> 0 | O6: =DSUM('KHACH HANG'!$E$5:$R$2133,"10",'KHACH HANG'!$AB$5:$AB$6) -> 0 | P6: =DSUM('KHACH HANG'!$E$5:$R$2133,"11",'KHACH HANG'!$AB$5:$AB$6) -> 0 | Q6: =DSUM('KHACH HANG'!$E$5:$R$2133,"12",'KHACH HANG'!$AB$5:$AB$6) -> 0 | R6: =SUM(F6:Q6) -> 41 | T6: AA | U6: 5 | V6: 6 | W6: DSUM('NHAN VIEN'!$E$5:$Q$2133,"1" | X6: ="DSUM('NHAN VIEN'!$E$5:$Q$2133,"&""""&$X$1&"""" -> DSUM('NHAN VIEN'!$E$5:$Q$2133,"2" | Y6: ="DSUM('NHAN VIEN'!$E$5:$Q$2133,"&""""&$Y$1&"""" -> DSUM('NHAN VIEN'!$E$5:$Q$2133,"3" | Z6: ="DSUM('NHAN VIEN'!$E$5:$Q$2133,"&""""&$Z$1&"""" -> DSUM('NHAN VIEN'!$E$5:$Q$2133,"4" | AA6: ="DSUM('NHAN VIEN'!$E$5:$Q$2133,"&""""&$AA$1&"""" -> DSUM('NHAN VIEN'!$E$5:$Q$2133,"5" | AB6: ="DSUM('NHAN VIEN'!$E$5:$Q$2133,"&""""&$AB$1&"""" -> DSUM('NHAN VIEN'!$E$5:$Q$2133,"6" | AC6: ="DSUM('NHAN VIEN'!$E$5:$Q$2133,"&""""&$AC$1&"""" -> DSUM('NHAN VIEN'!$E$5:$Q$2133,"7" | AD6: ="DSUM('NHAN VIEN'!$E$5:$Q$2133,"&""""&$AD$1&"""" -> DSUM('NHAN VIEN'!$E$5:$Q$2133,"8" | AE6: ="DSUM('NHAN VIEN'!$E$5:$Q$2133,"&""""&$AE$1&"""" -> DSUM('NHAN VIEN'!$E$5:$Q$2133,"9" | AF6: ="DSUM('NHAN VIEN'!$E$5:$Q$2133,"&""""&$AF$1&"""" -> DSUM('NHAN VIEN'!$E$5:$Q$2133,"10" | AG6: ="DSUM('NHAN VIEN'!$E$5:$Q$2133,"&""""&$AG$1&"""" -> DSUM('NHAN VIEN'!$E$5:$Q$2133,"11" | AH6: ="DSUM('NHAN VIEN'!$E$5:$Q$2133,"&""""&$AH$1&"""" -> DSUM('NHAN VIEN'!$E$5:$Q$2133,"12" | AI6: =W6&","&AV6&")" -> DSUM('NHAN VIEN'!$E$5:$Q$2133,"1",'NHAN VIEN'!$AA$5:$AA$6) | AJ6: =X6&","&AV6&")" -> DSUM('NHAN VIEN'!$E$5:$Q$2133,"2",'NHAN VIEN'!$AA$5:$AA$6) | AK6: =Y6&","&AV6&")" -> DSUM('NHAN VIEN'!$E$5:$Q$2133,"3",'NHAN VIEN'!$AA$5:$AA$6) | AL6: =Z6&","&AV6&")" -> DSUM('NHAN VIEN'!$E$5:$Q$2133,"4",'NHAN VIEN'!$AA$5:$AA$6) | AM6: =AA6&","&AV6&")" -> DSUM('NHAN VIEN'!$E$5:$Q$2133,"5",'NHAN VIEN'!$AA$5:$AA$6) | AN6: =AB6&","&AV6&")" -> DSUM('NHAN VIEN'!$E$5:$Q$2133,"6",'NHAN VIEN'!$AA$5:$AA$6) | AO6: =AC6&","&AV6&")" -> DSUM('NHAN VIEN'!$E$5:$Q$2133,"7",'NHAN VIEN'!$AA$5:$AA$6) | AP6: =AD6&","&AV6&")" -> DSUM('NHAN VIEN'!$E$5:$Q$2133,"8",'NHAN VIEN'!$AA$5:$AA$6) | AQ6: =AE6&","&AV6&")" -> DSUM('NHAN VIEN'!$E$5:$Q$2133,"9",'NHAN VIEN'!$AA$5:$AA$6) | AR6: =AF6&","&AV6&")" -> DSUM('NHAN VIEN'!$E$5:$Q$2133,"10",'NHAN VIEN'!$AA$5:$AA$6) | AS6: =AG6&","&AV6&")" -> DSUM('NHAN VIEN'!$E$5:$Q$2133,"11",'NHAN VIEN'!$AA$5:$AA$6) | AT6: =AH6&","&AV6&")" -> DSUM('NHAN VIEN'!$E$5:$Q$2133,"12",'NHAN VIEN'!$AA$5:$AA$6) | AV6: ="'NHAN VIEN'!$"&T6&"$"&U6&":$"&T6&"$"&V6 -> 'NHAN VIEN'!$AA$5:$AA$6 | AY6: ="="&AI6 -> =DSUM('NHAN VIEN'!$E$5:$Q$2133,"1",'NHAN VIEN'!$AA$5:$AA$6) | AZ6: ="="&AJ6 -> =DSUM('NHAN VIEN'!$E$5:$Q$2133,"2",'NHAN VIEN'!$AA$5:$AA$6) | BA6: ="="&AK6 -> =DSUM('NHAN VIEN'!$E$5:$Q$2133,"3",'NHAN VIEN'!$AA$5:$AA$6) | BB6: ="="&AL6 -> =DSUM('NHAN VIEN'!$E$5:$Q$2133,"4",'NHAN VIEN'!$AA$5:$AA$6) | BC6: ="="&AM6 -> =DSUM('NHAN VIEN'!$E$5:$Q$2133,"5",'NHAN VIEN'!$AA$5:$AA$6) | BD6: ="="&AN6 -> =DSUM('NHAN VIEN'!$E$5:$Q$2133,"6",'NHAN VIEN'!$AA$5:$AA$6) | BE6: ="="&AO6 -> =DSUM('NHAN VIEN'!$E$5:$Q$2133,"7",'NHAN VIEN'!$AA$5:$AA$6) | BF6: ="="&AP6 -> =DSUM('NHAN VIEN'!$E$5:$Q$2133,"8",'NHAN VIEN'!$AA$5:$AA$6) | ... BJ6: ="="&AT6 -> =DSUM('NHAN VIEN'!$E$5:$Q$2133,"12",'NHAN VIEN'!$AA$5:$AA$6) | BR6: =R6-'KHACH HANG'!S9 -> 6
B7: =B6+1 -> 5 | C7: =VLOOKUP(B7,DMSP!$A$1:$C$39,2,0) -> 2.HC | D7: =VLOOKUP(B7,DMSP!$A$1:$C$39,3,0) -> WOW | E7: =R7 -> 26 | F7: =DSUM('KHACH HANG'!$E$5:$R$2133,"1",'KHACH HANG'!$AC$5:$AC$6) -> 0 | G7: =DSUM('KHACH HANG'!$E$5:$R$2133,"2",'KHACH HANG'!$AC$5:$AC$6) -> 0 | H7: =DSUM('KHACH HANG'!$E$5:$R$2133,"3",'KHACH HANG'!$AC$5:$AC$6) -> 0 | I7: =DSUM('KHACH HANG'!$E$5:$R$2133,"4",'KHACH HANG'!$AC$5:$AC$6) -> 20 | J7: =DSUM('KHACH HANG'!$E$5:$R$2133,"5",'KHACH HANG'!$AC$5:$AC$6) -> 6 | K7: =DSUM('KHACH HANG'!$E$5:$R$2133,"6",'KHACH HANG'!$AC$5:$AC$6) -> 0 | L7: =DSUM('KHACH HANG'!$E$5:$R$2133,"7",'KHACH HANG'!$AC$5:$AC$6) -> 0 | M7: =DSUM('KHACH HANG'!$E$5:$R$2133,"8",'KHACH HANG'!$AC$5:$AC$6) -> 0 | N7: =DSUM('KHACH HANG'!$E$5:$R$2133,"9",'KHACH HANG'!$AC$5:$AC$6) -> 0 | O7: =DSUM('KHACH HANG'!$E$5:$R$2133,"10",'KHACH HANG'!$AC$5:$AC$6) -> 0 | P7: =DSUM('KHACH HANG'!$E$5:$R$2133,"11",'KHACH HANG'!$AC$5:$AC$6) -> 0 | Q7: =DSUM('KHACH HANG'!$E$5:$R$2133,"12",'KHACH HANG'!$AC$5:$AC$6) -> 0 | R7: =SUM(F7:Q7) -> 26 | T7: AB | U7: 5 | V7: 6 | W7: DSUM('NHAN VIEN'!$E$5:$Q$2133,"1" | X7: ="DSUM('NHAN VIEN'!$E$5:$Q$2133,"&""""&$X$1&"""" -> DSUM('NHAN VIEN'!$E$5:$Q$2133,"2" | Y7: ="DSUM('NHAN VIEN'!$E$5:$Q$2133,"&""""&$Y$1&"""" -> DSUM('NHAN VIEN'!$E$5:$Q$2133,"3" | Z7: ="DSUM('NHAN VIEN'!$E$5:$Q$2133,"&""""&$Z$1&"""" -> DSUM('NHAN VIEN'!$E$5:$Q$2133,"4" | AA7: ="DSUM('NHAN VIEN'!$E$5:$Q$2133,"&""""&$AA$1&"""" -> DSUM('NHAN VIEN'!$E$5:$Q$2133,"5" | AB7: ="DSUM('NHAN VIEN'!$E$5:$Q$2133,"&""""&$AB$1&"""" -> DSUM('NHAN VIEN'!$E$5:$Q$2133,"6" | AC7: ="DSUM('NHAN VIEN'!$E$5:$Q$2133,"&""""&$AC$1&"""" -> DSUM('NHAN VIEN'!$E$5:$Q$2133,"7" | AD7: ="DSUM('NHAN VIEN'!$E$5:$Q$2133,"&""""&$AD$1&"""" -> DSUM('NHAN VIEN'!$E$5:$Q$2133,"8" | AE7: ="DSUM('NHAN VIEN'!$E$5:$Q$2133,"&""""&$AE$1&"""" -> DSUM('NHAN VIEN'!$E$5:$Q$2133,"9" | AF7: ="DSUM('NHAN VIEN'!$E$5:$Q$2133,"&""""&$AF$1&"""" -> DSUM('NHAN VIEN'!$E$5:$Q$2133,"10" | AG7: ="DSUM('NHAN VIEN'!$E$5:$Q$2133,"&""""&$AG$1&"""" -> DSUM('NHAN VIEN'!$E$5:$Q$2133,"11" | AH7: ="DSUM('NHAN VIEN'!$E$5:$Q$2133,"&""""&$AH$1&"""" -> DSUM('NHAN VIEN'!$E$5:$Q$2133,"12" | AI7: =W7&","&AV7&")" -> DSUM('NHAN VIEN'!$E$5:$Q$2133,"1",'NHAN VIEN'!$AB$5:$AB$6) | AJ7: =X7&","&AV7&")" -> DSUM('NHAN VIEN'!$E$5:$Q$2133,"2",'NHAN VIEN'!$AB$5:$AB$6) | AK7: =Y7&","&AV7&")" -> DSUM('NHAN VIEN'!$E$5:$Q$2133,"3",'NHAN VIEN'!$AB$5:$AB$6) | AL7: =Z7&","&AV7&")" -> DSUM('NHAN VIEN'!$E$5:$Q$2133,"4",'NHAN VIEN'!$AB$5:$AB$6) | AM7: =AA7&","&AV7&")" -> DSUM('NHAN VIEN'!$E$5:$Q$2133,"5",'NHAN VIEN'!$AB$5:$AB$6) | AN7: =AB7&","&AV7&")" -> DSUM('NHAN VIEN'!$E$5:$Q$2133,"6",'NHAN VIEN'!$AB$5:$AB$6) | AO7: =AC7&","&AV7&")" -> DSUM('NHAN VIEN'!$E$5:$Q$2133,"7",'NHAN VIEN'!$AB$5:$AB$6) | AP7: =AD7&","&AV7&")" -> DSUM('NHAN VIEN'!$E$5:$Q$2133,"8",'NHAN VIEN'!$AB$5:$AB$6) | AQ7: =AE7&","&AV7&")" -> DSUM('NHAN VIEN'!$E$5:$Q$2133,"9",'NHAN VIEN'!$AB$5:$AB$6) | AR7: =AF7&","&AV7&")" -> DSUM('NHAN VIEN'!$E$5:$Q$2133,"10",'NHAN VIEN'!$AB$5:$AB$6) | AS7: =AG7&","&AV7&")" -> DSUM('NHAN VIEN'!$E$5:$Q$2133,"11",'NHAN VIEN'!$AB$5:$AB$6) | AT7: =AH7&","&AV7&")" -> DSUM('NHAN VIEN'!$E$5:$Q$2133,"12",'NHAN VIEN'!$AB$5:$AB$6) | AV7: ="'NHAN VIEN'!$"&T7&"$"&U7&":$"&T7&"$"&V7 -> 'NHAN VIEN'!$AB$5:$AB$6 | AY7: ="="&AI7 -> =DSUM('NHAN VIEN'!$E$5:$Q$2133,"1",'NHAN VIEN'!$AB$5:$AB$6) | AZ7: ="="&AJ7 -> =DSUM('NHAN VIEN'!$E$5:$Q$2133,"2",'NHAN VIEN'!$AB$5:$AB$6) | BA7: ="="&AK7 -> =DSUM('NHAN VIEN'!$E$5:$Q$2133,"3",'NHAN VIEN'!$AB$5:$AB$6) | BB7: ="="&AL7 -> =DSUM('NHAN VIEN'!$E$5:$Q$2133,"4",'NHAN VIEN'!$AB$5:$AB$6) | BC7: ="="&AM7 -> =DSUM('NHAN VIEN'!$E$5:$Q$2133,"5",'NHAN VIEN'!$AB$5:$AB$6) | BD7: ="="&AN7 -> =DSUM('NHAN VIEN'!$E$5:$Q$2133,"6",'NHAN VIEN'!$AB$5:$AB$6) | BE7: ="="&AO7 -> =DSUM('NHAN VIEN'!$E$5:$Q$2133,"7",'NHAN VIEN'!$AB$5:$AB$6) | BF7: ="="&AP7 -> =DSUM('NHAN VIEN'!$E$5:$Q$2133,"8",'NHAN VIEN'!$AB$5:$AB$6) | ... BJ7: ="="&AT7 -> =DSUM('NHAN VIEN'!$E$5:$Q$2133,"12",'NHAN VIEN'!$AB$5:$AB$6) | BR7: =R7-'KHACH HANG'!S10 -> 26
B8: =B7+1 -> 6 | C8: =VLOOKUP(B8,DMSP!$A$1:$C$39,2,0) -> 3.SPRAY | D8: =VLOOKUP(B8,DMSP!$A$1:$C$39,3,0) -> KELPIT | E8: =R8 -> 36 | F8: =DSUM('KHACH HANG'!$E$5:$R$2133,"1",'KHACH HANG'!$AD$5:$AD$6) -> 14 | G8: =DSUM('KHACH HANG'!$E$5:$R$2133,"2",'KHACH HANG'!$AD$5:$AD$6) -> 14 | H8: =DSUM('KHACH HANG'!$E$5:$R$2133,"3",'KHACH HANG'!$AD$5:$AD$6) -> 0 | I8: =DSUM('KHACH HANG'!$E$5:$R$2133,"4",'KHACH HANG'!$AD$5:$AD$6) -> 0 | J8: =DSUM('KHACH HANG'!$E$5:$R$2133,"5",'KHACH HANG'!$AD$5:$AD$6) -> 0 | K8: =DSUM('KHACH HANG'!$E$5:$R$2133,"6",'KHACH HANG'!$AD$5:$AD$6) -> 0 | L8: =DSUM('KHACH HANG'!$E$5:$R$2133,"7",'KHACH HANG'!$AD$5:$AD$6) -> 0 | M8: =DSUM('KHACH HANG'!$E$5:$R$2133,"8",'KHACH HANG'!$AD$5:$AD$6) -> 0 | N8: =DSUM('KHACH HANG'!$E$5:$R$2133,"9",'KHACH HANG'!$AD$5:$AD$6) -> 0 | O8: =DSUM('KHACH HANG'!$E$5:$R$2133,"10",'KHACH HANG'!$AD$5:$AD$6) -> 0 | P8: =DSUM('KHACH HANG'!$E$5:$R$2133,"11",'KHACH HANG'!$AD$5:$AD$6) -> 0 | Q8: =DSUM('KHACH HANG'!$E$5:$R$2133,"12",'KHACH HANG'!$AD$5:$AD$6) -> 8 | R8: =SUM(F8:Q8) -> 36 | T8: AC | U8: 5 | V8: 6 | W8: DSUM('NHAN VIEN'!$E$5:$Q$2133,"1" | X8: ="DSUM('NHAN VIEN'!$E$5:$Q$2133,"&""""&$X$1&"""" -> DSUM('NHAN VIEN'!$E$5:$Q$2133,"2" | Y8: ="DSUM('NHAN VIEN'!$E$5:$Q$2133,"&""""&$Y$1&"""" -> DSUM('NHAN VIEN'!$E$5:$Q$2133,"3" | Z8: ="DSUM('NHAN VIEN'!$E$5:$Q$2133,"&""""&$Z$1&"""" -> DSUM('NHAN VIEN'!$E$5:$Q$2133,"4" | AA8: ="DSUM('NHAN VIEN'!$E$5:$Q$2133,"&""""&$AA$1&"""" -> DSUM('NHAN VIEN'!$E$5:$Q$2133,"5" | AB8: ="DSUM('NHAN VIEN'!$E$5:$Q$2133,"&""""&$AB$1&"""" -> DSUM('NHAN VIEN'!$E$5:$Q$2133,"6" | AC8: ="DSUM('NHAN VIEN'!$E$5:$Q$2133,"&""""&$AC$1&"""" -> DSUM('NHAN VIEN'!$E$5:$Q$2133,"7" | AD8: ="DSUM('NHAN VIEN'!$E$5:$Q$2133,"&""""&$AD$1&"""" -> DSUM('NHAN VIEN'!$E$5:$Q$2133,"8" | AE8: ="DSUM('NHAN VIEN'!$E$5:$Q$2133,"&""""&$AE$1&"""" -> DSUM('NHAN VIEN'!$E$5:$Q$2133,"9" | AF8: ="DSUM('NHAN VIEN'!$E$5:$Q$2133,"&""""&$AF$1&"""" -> DSUM('NHAN VIEN'!$E$5:$Q$2133,"10" | AG8: ="DSUM('NHAN VIEN'!$E$5:$Q$2133,"&""""&$AG$1&"""" -> DSUM('NHAN VIEN'!$E$5:$Q$2133,"11" | AH8: ="DSUM('NHAN VIEN'!$E$5:$Q$2133,"&""""&$AH$1&"""" -> DSUM('NHAN VIEN'!$E$5:$Q$2133,"12" | AI8: =W8&","&AV8&")" -> DSUM('NHAN VIEN'!$E$5:$Q$2133,"1",'NHAN VIEN'!$AC$5:$AC$6) | AJ8: =X8&","&AV8&")" -> DSUM('NHAN VIEN'!$E$5:$Q$2133,"2",'NHAN VIEN'!$AC$5:$AC$6) | AK8: =Y8&","&AV8&")" -> DSUM('NHAN VIEN'!$E$5:$Q$2133,"3",'NHAN VIEN'!$AC$5:$AC$6) | AL8: =Z8&","&AV8&")" -> DSUM('NHAN VIEN'!$E$5:$Q$2133,"4",'NHAN VIEN'!$AC$5:$AC$6) | AM8: =AA8&","&AV8&")" -> DSUM('NHAN VIEN'!$E$5:$Q$2133,"5",'NHAN VIEN'!$AC$5:$AC$6) | AN8: =AB8&","&AV8&")" -> DSUM('NHAN VIEN'!$E$5:$Q$2133,"6",'NHAN VIEN'!$AC$5:$AC$6) | AO8: =AC8&","&AV8&")" -> DSUM('NHAN VIEN'!$E$5:$Q$2133,"7",'NHAN VIEN'!$AC$5:$AC$6) | AP8: =AD8&","&AV8&")" -> DSUM('NHAN VIEN'!$E$5:$Q$2133,"8",'NHAN VIEN'!$AC$5:$AC$6) | AQ8: =AE8&","&AV8&")" -> DSUM('NHAN VIEN'!$E$5:$Q$2133,"9",'NHAN VIEN'!$AC$5:$AC$6) | AR8: =AF8&","&AV8&")" -> DSUM('NHAN VIEN'!$E$5:$Q$2133,"10",'NHAN VIEN'!$AC$5:$AC$6) | AS8: =AG8&","&AV8&")" -> DSUM('NHAN VIEN'!$E$5:$Q$2133,"11",'NHAN VIEN'!$AC$5:$AC$6) | AT8: =AH8&","&AV8&")" -> DSUM('NHAN VIEN'!$E$5:$Q$2133,"12",'NHAN VIEN'!$AC$5:$AC$6) | AV8: ="'NHAN VIEN'!$"&T8&"$"&U8&":$"&T8&"$"&V8 -> 'NHAN VIEN'!$AC$5:$AC$6 | AY8: ="="&AI8 -> =DSUM('NHAN VIEN'!$E$5:$Q$2133,"1",'NHAN VIEN'!$AC$5:$AC$6) | AZ8: ="="&AJ8 -> =DSUM('NHAN VIEN'!$E$5:$Q$2133,"2",'NHAN VIEN'!$AC$5:$AC$6) | BA8: ="="&AK8 -> =DSUM('NHAN VIEN'!$E$5:$Q$2133,"3",'NHAN VIEN'!$AC$5:$AC$6) | BB8: ="="&AL8 -> =DSUM('NHAN VIEN'!$E$5:$Q$2133,"4",'NHAN VIEN'!$AC$5:$AC$6) | BC8: ="="&AM8 -> =DSUM('NHAN VIEN'!$E$5:$Q$2133,"5",'NHAN VIEN'!$AC$5:$AC$6) | BD8: ="="&AN8 -> =DSUM('NHAN VIEN'!$E$5:$Q$2133,"6",'NHAN VIEN'!$AC$5:$AC$6) | BE8: ="="&AO8 -> =DSUM('NHAN VIEN'!$E$5:$Q$2133,"7",'NHAN VIEN'!$AC$5:$AC$6) | BF8: ="="&AP8 -> =DSUM('NHAN VIEN'!$E$5:$Q$2133,"8",'NHAN VIEN'!$AC$5:$AC$6) | ... BJ8: ="="&AT8 -> =DSUM('NHAN VIEN'!$E$5:$Q$2133,"12",'NHAN VIEN'!$AC$5:$AC$6) | BR8: =R8-'KHACH HANG'!S11 -> 36
B9: =B8+1 -> 7 | C9: =VLOOKUP(B9,DMSP!$A$1:$C$39,2,0) -> 3.SPRAY | D9: =VLOOKUP(B9,DMSP!$A$1:$C$39,3,0) -> SI-K | E9: =R9 -> 127 | F9: =DSUM('KHACH HANG'!$E$5:$R$2133,"1",'KHACH HANG'!$Y$7:$Y$8) -> 0 | G9: =DSUM('KHACH HANG'!$E$5:$R$2133,"2",'KHACH HANG'!$Y$7:$Y$8) -> 0 | H9: =DSUM('KHACH HANG'!$E$5:$R$2133,"3",'KHACH HANG'!$Y$7:$Y$8) -> 0 | I9: =DSUM('KHACH HANG'!$E$5:$R$2133,"4",'KHACH HANG'!$Y$7:$Y$8) -> 0 | J9: =DSUM('KHACH HANG'!$E$5:$R$2133,"5",'KHACH HANG'!$Y$7:$Y$8) -> 49 | K9: =DSUM('KHACH HANG'!$E$5:$R$2133,"6",'KHACH HANG'!$Y$7:$Y$8) -> 49 | L9: =DSUM('KHACH HANG'!$E$5:$R$2133,"7",'KHACH HANG'!$Y$7:$Y$8) -> 5 | M9: =DSUM('KHACH HANG'!$E$5:$R$2133,"8",'KHACH HANG'!$Y$7:$Y$8) -> 0 | N9: =DSUM('KHACH HANG'!$E$5:$R$2133,"9",'KHACH HANG'!$Y$7:$Y$8) -> 0 | O9: =DSUM('KHACH HANG'!$E$5:$R$2133,"10",'KHACH HANG'!$Y$7:$Y$8) -> 0 | P9: =DSUM('KHACH HANG'!$E$5:$R$2133,"11",'KHACH HANG'!$Y$7:$Y$8) -> 5 | Q9: =DSUM('KHACH HANG'!$E$5:$R$2133,"12",'KHACH HANG'!$Y$7:$Y$8) -> 19 | R9: =SUM(F9:Q9) -> 127 | T9: X | U9: 7 | V9: 8 | W9: DSUM('NHAN VIEN'!$E$5:$Q$2133,"1" | X9: ="DSUM('NHAN VIEN'!$E$5:$Q$2133,"&""""&$X$1&"""" -> DSUM('NHAN VIEN'!$E$5:$Q$2133,"2" | Y9: ="DSUM('NHAN VIEN'!$E$5:$Q$2133,"&""""&$Y$1&"""" -> DSUM('NHAN VIEN'!$E$5:$Q$2133,"3" | Z9: ="DSUM('NHAN VIEN'!$E$5:$Q$2133,"&""""&$Z$1&"""" -> DSUM('NHAN VIEN'!$E$5:$Q$2133,"4" | AA9: ="DSUM('NHAN VIEN'!$E$5:$Q$2133,"&""""&$AA$1&"""" -> DSUM('NHAN VIEN'!$E$5:$Q$2133,"5" | AB9: ="DSUM('NHAN VIEN'!$E$5:$Q$2133,"&""""&$AB$1&"""" -> DSUM('NHAN VIEN'!$E$5:$Q$2133,"6" | AC9: ="DSUM('NHAN VIEN'!$E$5:$Q$2133,"&""""&$AC$1&"""" -> DSUM('NHAN VIEN'!$E$5:$Q$2133,"7" | AD9: ="DSUM('NHAN VIEN'!$E$5:$Q$2133,"&""""&$AD$1&"""" -> DSUM('NHAN VIEN'!$E$5:$Q$2133,"8" | AE9: ="DSUM('NHAN VIEN'!$E$5:$Q$2133,"&""""&$AE$1&"""" -> DSUM('NHAN VIEN'!$E$5:$Q$2133,"9" | AF9: ="DSUM('NHAN VIEN'!$E$5:$Q$2133,"&""""&$AF$1&"""" -> DSUM('NHAN VIEN'!$E$5:$Q$2133,"10" | AG9: ="DSUM('NHAN VIEN'!$E$5:$Q$2133,"&""""&$AG$1&"""" -> DSUM('NHAN VIEN'!$E$5:$Q$2133,"11" | AH9: ="DSUM('NHAN VIEN'!$E$5:$Q$2133,"&""""&$AH$1&"""" -> DSUM('NHAN VIEN'!$E$5:$Q$2133,"12" | AI9: =W9&","&AV9&")" -> DSUM('NHAN VIEN'!$E$5:$Q$2133,"1",'NHAN VIEN'!$X$7:$X$8) | AJ9: =X9&","&AV9&")" -> DSUM('NHAN VIEN'!$E$5:$Q$2133,"2",'NHAN VIEN'!$X$7:$X$8) | AK9: =Y9&","&AV9&")" -> DSUM('NHAN VIEN'!$E$5:$Q$2133,"3",'NHAN VIEN'!$X$7:$X$8) | AL9: =Z9&","&AV9&")" -> DSUM('NHAN VIEN'!$E$5:$Q$2133,"4",'NHAN VIEN'!$X$7:$X$8) | AM9: =AA9&","&AV9&")" -> DSUM('NHAN VIEN'!$E$5:$Q$2133,"5",'NHAN VIEN'!$X$7:$X$8) | AN9: =AB9&","&AV9&")" -> DSUM('NHAN VIEN'!$E$5:$Q$2133,"6",'NHAN VIEN'!$X$7:$X$8) | AO9: =AC9&","&AV9&")" -> DSUM('NHAN VIEN'!$E$5:$Q$2133,"7",'NHAN VIEN'!$X$7:$X$8) | AP9: =AD9&","&AV9&")" -> DSUM('NHAN VIEN'!$E$5:$Q$2133,"8",'NHAN VIEN'!$X$7:$X$8) | AQ9: =AE9&","&AV9&")" -> DSUM('NHAN VIEN'!$E$5:$Q$2133,"9",'NHAN VIEN'!$X$7:$X$8) | AR9: =AF9&","&AV9&")" -> DSUM('NHAN VIEN'!$E$5:$Q$2133,"10",'NHAN VIEN'!$X$7:$X$8) | AS9: =AG9&","&AV9&")" -> DSUM('NHAN VIEN'!$E$5:$Q$2133,"11",'NHAN VIEN'!$X$7:$X$8) | AT9: =AH9&","&AV9&")" -> DSUM('NHAN VIEN'!$E$5:$Q$2133,"12",'NHAN VIEN'!$X$7:$X$8) | AV9: ="'NHAN VIEN'!$"&T9&"$"&U9&":$"&T9&"$"&V9 -> 'NHAN VIEN'!$X$7:$X$8 | AY9: ="="&AI9 -> =DSUM('NHAN VIEN'!$E$5:$Q$2133,"1",'NHAN VIEN'!$X$7:$X$8) | AZ9: ="="&AJ9 -> =DSUM('NHAN VIEN'!$E$5:$Q$2133,"2",'NHAN VIEN'!$X$7:$X$8) | BA9: ="="&AK9 -> =DSUM('NHAN VIEN'!$E$5:$Q$2133,"3",'NHAN VIEN'!$X$7:$X$8) | BB9: ="="&AL9 -> =DSUM('NHAN VIEN'!$E$5:$Q$2133,"4",'NHAN VIEN'!$X$7:$X$8) | BC9: ="="&AM9 -> =DSUM('NHAN VIEN'!$E$5:$Q$2133,"5",'NHAN VIEN'!$X$7:$X$8) | BD9: ="="&AN9 -> =DSUM('NHAN VIEN'!$E$5:$Q$2133,"6",'NHAN VIEN'!$X$7:$X$8) | BE9: ="="&AO9 -> =DSUM('NHAN VIEN'!$E$5:$Q$2133,"7",'NHAN VIEN'!$X$7:$X$8) | BF9: ="="&AP9 -> =DSUM('NHAN VIEN'!$E$5:$Q$2133,"8",'NHAN VIEN'!$X$7:$X$8) | ... BJ9: ="="&AT9 -> =DSUM('NHAN VIEN'!$E$5:$Q$2133,"12",'NHAN VIEN'!$X$7:$X$8) | BR9: =R9-'KHACH HANG'!S12 -> 53
B10: =B9+1 -> 8 | C10: =VLOOKUP(B10,DMSP!$A$1:$C$39,2,0) -> 3.SPRAY | D10: =VLOOKUP(B10,DMSP!$A$1:$C$39,3,0) -> SPRAY PHOS 620 | E10: =R10 -> 240 | F10: =DSUM('KHACH HANG'!$E$5:$R$2133,"1",'KHACH HANG'!$Z$7:$Z$8) -> 23 | G10: =DSUM('KHACH HANG'!$E$5:$R$2133,"2",'KHACH HANG'!$Z$7:$Z$8) -> 0 | H10: =DSUM('KHACH HANG'!$E$5:$R$2133,"3",'KHACH HANG'!$Z$7:$Z$8) -> 0 | I10: =DSUM('KHACH HANG'!$E$5:$R$2133,"4",'KHACH HANG'!$Z$7:$Z$8) -> 86 | J10: =DSUM('KHACH HANG'!$E$5:$R$2133,"5",'KHACH HANG'!$Z$7:$Z$8) -> 45 | K10: =DSUM('KHACH HANG'!$E$5:$R$2133,"6",'KHACH HANG'!$Z$7:$Z$8) -> 0 | L10: =DSUM('KHACH HANG'!$E$5:$R$2133,"7",'KHACH HANG'!$Z$7:$Z$8) -> 14 | M10: =DSUM('KHACH HANG'!$E$5:$R$2133,"8",'KHACH HANG'!$Z$7:$Z$8) -> 0 | N10: =DSUM('KHACH HANG'!$E$5:$R$2133,"9",'KHACH HANG'!$Z$7:$Z$8) -> 0 | O10: =DSUM('KHACH HANG'!$E$5:$R$2133,"10",'KHACH HANG'!$Z$7:$Z$8) -> 14 | P10: =DSUM('KHACH HANG'!$E$5:$R$2133,"11",'KHACH HANG'!$Z$7:$Z$8) -> 14 | Q10: =DSUM('KHACH HANG'!$E$5:$R$2133,"12",'KHACH HANG'!$Z$7:$Z$8) -> 44 | R10: =SUM(F10:Q10) -> 240 | T10: Y | U10: 7 | V10: 8 | W10: DSUM('NHAN VIEN'!$E$5:$Q$2133,"1" | X10: ="DSUM('NHAN VIEN'!$E$5:$Q$2133,"&""""&$X$1&"""" -> DSUM('NHAN VIEN'!$E$5:$Q$2133,"2" | Y10: ="DSUM('NHAN VIEN'!$E$5:$Q$2133,"&""""&$Y$1&"""" -> DSUM('NHAN VIEN'!$E$5:$Q$2133,"3" | Z10: ="DSUM('NHAN VIEN'!$E$5:$Q$2133,"&""""&$Z$1&"""" -> DSUM('NHAN VIEN'!$E$5:$Q$2133,"4" | AA10: ="DSUM('NHAN VIEN'!$E$5:$Q$2133,"&""""&$AA$1&"""" -> DSUM('NHAN VIEN'!$E$5:$Q$2133,"5" | AB10: ="DSUM('NHAN VIEN'!$E$5:$Q$2133,"&""""&$AB$1&"""" -> DSUM('NHAN VIEN'!$E$5:$Q$2133,"6" | AC10: ="DSUM('NHAN VIEN'!$E$5:$Q$2133,"&""""&$AC$1&"""" -> DSUM('NHAN VIEN'!$E$5:$Q$2133,"7" | AD10: ="DSUM('NHAN VIEN'!$E$5:$Q$2133,"&""""&$AD$1&"""" -> DSUM('NHAN VIEN'!$E$5:$Q$2133,"8" | AE10: ="DSUM('NHAN VIEN'!$E$5:$Q$2133,"&""""&$AE$1&"""" -> DSUM('NHAN VIEN'!$E$5:$Q$2133,"9" | AF10: ="DSUM('NHAN VIEN'!$E$5:$Q$2133,"&""""&$AF$1&"""" -> DSUM('NHAN VIEN'!$E$5:$Q$2133,"10" | AG10: ="DSUM('NHAN VIEN'!$E$5:$Q$2133,"&""""&$AG$1&"""" -> DSUM('NHAN VIEN'!$E$5:$Q$2133,"11" | AH10: ="DSUM('NHAN VIEN'!$E$5:$Q$2133,"&""""&$AH$1&"""" -> DSUM('NHAN VIEN'!$E$5:$Q$2133,"12" | AI10: =W10&","&AV10&")" -> DSUM('NHAN VIEN'!$E$5:$Q$2133,"1",'NHAN VIEN'!$Y$7:$Y$8) | AJ10: =X10&","&AV10&")" -> DSUM('NHAN VIEN'!$E$5:$Q$2133,"2",'NHAN VIEN'!$Y$7:$Y$8) | AK10: =Y10&","&AV10&")" -> DSUM('NHAN VIEN'!$E$5:$Q$2133,"3",'NHAN VIEN'!$Y$7:$Y$8) | AL10: =Z10&","&AV10&")" -> DSUM('NHAN VIEN'!$E$5:$Q$2133,"4",'NHAN VIEN'!$Y$7:$Y$8) | AM10: =AA10&","&AV10&")" -> DSUM('NHAN VIEN'!$E$5:$Q$2133,"5",'NHAN VIEN'!$Y$7:$Y$8) | AN10: =AB10&","&AV10&")" -> DSUM('NHAN VIEN'!$E$5:$Q$2133,"6",'NHAN VIEN'!$Y$7:$Y$8) | AO10: =AC10&","&AV10&")" -> DSUM('NHAN VIEN'!$E$5:$Q$2133,"7",'NHAN VIEN'!$Y$7:$Y$8) | AP10: =AD10&","&AV10&")" -> DSUM('NHAN VIEN'!$E$5:$Q$2133,"8",'NHAN VIEN'!$Y$7:$Y$8) | AQ10: =AE10&","&AV10&")" -> DSUM('NHAN VIEN'!$E$5:$Q$2133,"9",'NHAN VIEN'!$Y$7:$Y$8) | AR10: =AF10&","&AV10&")" -> DSUM('NHAN VIEN'!$E$5:$Q$2133,"10",'NHAN VIEN'!$Y$7:$Y$8) | AS10: =AG10&","&AV10&")" -> DSUM('NHAN VIEN'!$E$5:$Q$2133,"11",'NHAN VIEN'!$Y$7:$Y$8) | AT10: =AH10&","&AV10&")" -> DSUM('NHAN VIEN'!$E$5:$Q$2133,"12",'NHAN VIEN'!$Y$7:$Y$8) | AV10: ="'NHAN VIEN'!$"&T10&"$"&U10&":$"&T10&"$"&V10 -> 'NHAN VIEN'!$Y$7:$Y$8 | AY10: ="="&AI10 -> =DSUM('NHAN VIEN'!$E$5:$Q$2133,"1",'NHAN VIEN'!$Y$7:$Y$8) | AZ10: ="="&AJ10 -> =DSUM('NHAN VIEN'!$E$5:$Q$2133,"2",'NHAN VIEN'!$Y$7:$Y$8) | BA10: ="="&AK10 -> =DSUM('NHAN VIEN'!$E$5:$Q$2133,"3",'NHAN VIEN'!$Y$7:$Y$8) | BB10: ="="&AL10 -> =DSUM('NHAN VIEN'!$E$5:$Q$2133,"4",'NHAN VIEN'!$Y$7:$Y$8) | BC10: ="="&AM10 -> =DSUM('NHAN VIEN'!$E$5:$Q$2133,"5",'NHAN VIEN'!$Y$7:$Y$8) | BD10: ="="&AN10 -> =DSUM('NHAN VIEN'!$E$5:$Q$2133,"6",'NHAN VIEN'!$Y$7:$Y$8) | BE10: ="="&AO10 -> =DSUM('NHAN VIEN'!$E$5:$Q$2133,"7",'NHAN VIEN'!$Y$7:$Y$8) | BF10: ="="&AP10 -> =DSUM('NHAN VIEN'!$E$5:$Q$2133,"8",'NHAN VIEN'!$Y$7:$Y$8) | ... BJ10: ="="&AT10 -> =DSUM('NHAN VIEN'!$E$5:$Q$2133,"12",'NHAN VIEN'!$Y$7:$Y$8) | BR10: =R10-'KHACH HANG'!S13 -> 217
B11: =B10+1 -> 9 | C11: =VLOOKUP(B11,DMSP!$A$1:$C$39,2,0) -> 4.DƯỠNG RỄ | D11: =VLOOKUP(B11,DMSP!$A$1:$C$39,3,0) -> CHITOSAN | E11: =R11 -> 0 | F11: =DSUM('KHACH HANG'!$E$5:$R$2133,"1",'KHACH HANG'!$AA$7:$AA$8) -> 0 | G11: =DSUM('KHACH HANG'!$E$5:$R$2133,"2",'KHACH HANG'!$AA$7:$AA$8) -> 0 | H11: =DSUM('KHACH HANG'!$E$5:$R$2133,"3",'KHACH HANG'!$AA$7:$AA$8) -> 0 | I11: =DSUM('KHACH HANG'!$E$5:$R$2133,"4",'KHACH HANG'!$AA$7:$AA$8) -> 0 | J11: =DSUM('KHACH HANG'!$E$5:$R$2133,"5",'KHACH HANG'!$AA$7:$AA$8) -> 0 | K11: =DSUM('KHACH HANG'!$E$5:$R$2133,"6",'KHACH HANG'!$AA$7:$AA$8) -> 0 | L11: =DSUM('KHACH HANG'!$E$5:$R$2133,"7",'KHACH HANG'!$AA$7:$AA$8) -> 0 | M11: =DSUM('KHACH HANG'!$E$5:$R$2133,"8",'KHACH HANG'!$AA$7:$AA$8) -> 0 | N11: =DSUM('KHACH HANG'!$E$5:$R$2133,"9",'KHACH HANG'!$AA$7:$AA$8) -> 0 | O11: =DSUM('KHACH HANG'!$E$5:$R$2133,"10",'KHACH HANG'!$AA$7:$AA$8) -> 0 | P11: =DSUM('KHACH HANG'!$E$5:$R$2133,"11",'KHACH HANG'!$AA$7:$AA$8) -> 0 | Q11: =DSUM('KHACH HANG'!$E$5:$R$2133,"12",'KHACH HANG'!$AA$7:$AA$8) -> 0 | R11: =SUM(F11:Q11) -> 0 | T11: Z | U11: 7 | V11: 8 | W11: DSUM('NHAN VIEN'!$E$5:$Q$2133,"1" | X11: ="DSUM('NHAN VIEN'!$E$5:$Q$2133,"&""""&$X$1&"""" -> DSUM('NHAN VIEN'!$E$5:$Q$2133,"2" | Y11: ="DSUM('NHAN VIEN'!$E$5:$Q$2133,"&""""&$Y$1&"""" -> DSUM('NHAN VIEN'!$E$5:$Q$2133,"3" | Z11: ="DSUM('NHAN VIEN'!$E$5:$Q$2133,"&""""&$Z$1&"""" -> DSUM('NHAN VIEN'!$E$5:$Q$2133,"4" | AA11: ="DSUM('NHAN VIEN'!$E$5:$Q$2133,"&""""&$AA$1&"""" -> DSUM('NHAN VIEN'!$E$5:$Q$2133,"5" | AB11: ="DSUM('NHAN VIEN'!$E$5:$Q$2133,"&""""&$AB$1&"""" -> DSUM('NHAN VIEN'!$E$5:$Q$2133,"6" | AC11: ="DSUM('NHAN VIEN'!$E$5:$Q$2133,"&""""&$AC$1&"""" -> DSUM('NHAN VIEN'!$E$5:$Q$2133,"7" | AD11: ="DSUM('NHAN VIEN'!$E$5:$Q$2133,"&""""&$AD$1&"""" -> DSUM('NHAN VIEN'!$E$5:$Q$2133,"8" | AE11: ="DSUM('NHAN VIEN'!$E$5:$Q$2133,"&""""&$AE$1&"""" -> DSUM('NHAN VIEN'!$E$5:$Q$2133,"9" | AF11: ="DSUM('NHAN VIEN'!$E$5:$Q$2133,"&""""&$AF$1&"""" -> DSUM('NHAN VIEN'!$E$5:$Q$2133,"10" | AG11: ="DSUM('NHAN VIEN'!$E$5:$Q$2133,"&""""&$AG$1&"""" -> DSUM('NHAN VIEN'!$E$5:$Q$2133,"11" | AH11: ="DSUM('NHAN VIEN'!$E$5:$Q$2133,"&""""&$AH$1&"""" -> DSUM('NHAN VIEN'!$E$5:$Q$2133,"12" | AI11: =W11&","&AV11&")" -> DSUM('NHAN VIEN'!$E$5:$Q$2133,"1",'NHAN VIEN'!$Z$7:$Z$8) | AJ11: =X11&","&AV11&")" -> DSUM('NHAN VIEN'!$E$5:$Q$2133,"2",'NHAN VIEN'!$Z$7:$Z$8) | AK11: =Y11&","&AV11&")" -> DSUM('NHAN VIEN'!$E$5:$Q$2133,"3",'NHAN VIEN'!$Z$7:$Z$8) | AL11: =Z11&","&AV11&")" -> DSUM('NHAN VIEN'!$E$5:$Q$2133,"4",'NHAN VIEN'!$Z$7:$Z$8) | AM11: =AA11&","&AV11&")" -> DSUM('NHAN VIEN'!$E$5:$Q$2133,"5",'NHAN VIEN'!$Z$7:$Z$8) | AN11: =AB11&","&AV11&")" -> DSUM('NHAN VIEN'!$E$5:$Q$2133,"6",'NHAN VIEN'!$Z$7:$Z$8) | AO11: =AC11&","&AV11&")" -> DSUM('NHAN VIEN'!$E$5:$Q$2133,"7",'NHAN VIEN'!$Z$7:$Z$8) | AP11: =AD11&","&AV11&")" -> DSUM('NHAN VIEN'!$E$5:$Q$2133,"8",'NHAN VIEN'!$Z$7:$Z$8) | AQ11: =AE11&","&AV11&")" -> DSUM('NHAN VIEN'!$E$5:$Q$2133,"9",'NHAN VIEN'!$Z$7:$Z$8) | AR11: =AF11&","&AV11&")" -> DSUM('NHAN VIEN'!$E$5:$Q$2133,"10",'NHAN VIEN'!$Z$7:$Z$8) | AS11: =AG11&","&AV11&")" -> DSUM('NHAN VIEN'!$E$5:$Q$2133,"11",'NHAN VIEN'!$Z$7:$Z$8) | AT11: =AH11&","&AV11&")" -> DSUM('NHAN VIEN'!$E$5:$Q$2133,"12",'NHAN VIEN'!$Z$7:$Z$8) | AV11: ="'NHAN VIEN'!$"&T11&"$"&U11&":$"&T11&"$"&V11 -> 'NHAN VIEN'!$Z$7:$Z$8 | AY11: ="="&AI11 -> =DSUM('NHAN VIEN'!$E$5:$Q$2133,"1",'NHAN VIEN'!$Z$7:$Z$8) | AZ11: ="="&AJ11 -> =DSUM('NHAN VIEN'!$E$5:$Q$2133,"2",'NHAN VIEN'!$Z$7:$Z$8) | BA11: ="="&AK11 -> =DSUM('NHAN VIEN'!$E$5:$Q$2133,"3",'NHAN VIEN'!$Z$7:$Z$8) | BB11: ="="&AL11 -> =DSUM('NHAN VIEN'!$E$5:$Q$2133,"4",'NHAN VIEN'!$Z$7:$Z$8) | BC11: ="="&AM11 -> =DSUM('NHAN VIEN'!$E$5:$Q$2133,"5",'NHAN VIEN'!$Z$7:$Z$8) | BD11: ="="&AN11 -> =DSUM('NHAN VIEN'!$E$5:$Q$2133,"6",'NHAN VIEN'!$Z$7:$Z$8) | BE11: ="="&AO11 -> =DSUM('NHAN VIEN'!$E$5:$Q$2133,"7",'NHAN VIEN'!$Z$7:$Z$8) | BF11: ="="&AP11 -> =DSUM('NHAN VIEN'!$E$5:$Q$2133,"8",'NHAN VIEN'!$Z$7:$Z$8) | ... BJ11: ="="&AT11 -> =DSUM('NHAN VIEN'!$E$5:$Q$2133,"12",'NHAN VIEN'!$Z$7:$Z$8) | BR11: =R11-'KHACH HANG'!S14 -> 0
B12: =B11+1 -> 10 | C12: =VLOOKUP(B12,DMSP!$A$1:$C$39,2,0) -> 4.DƯỠNG RỄ | D12: =VLOOKUP(B12,DMSP!$A$1:$C$39,3,0) -> ĐẠM CÁ | E12: =R12 -> 0 | F12: =DSUM('KHACH HANG'!$E$5:$R$2133,"1",'KHACH HANG'!$AB$7:$AB$8) -> 0 | G12: =DSUM('KHACH HANG'!$E$5:$R$2133,"2",'KHACH HANG'!$AB$7:$AB$8) -> 0 | H12: =DSUM('KHACH HANG'!$E$5:$R$2133,"3",'KHACH HANG'!$AB$7:$AB$8) -> 0 | I12: =DSUM('KHACH HANG'!$E$5:$R$2133,"4",'KHACH HANG'!$AB$7:$AB$8) -> 0 | J12: =DSUM('KHACH HANG'!$E$5:$R$2133,"5",'KHACH HANG'!$AB$7:$AB$8) -> 0 | K12: =DSUM('KHACH HANG'!$E$5:$R$2133,"6",'KHACH HANG'!$AB$7:$AB$8) -> 0 | L12: =DSUM('KHACH HANG'!$E$5:$R$2133,"7",'KHACH HANG'!$AB$7:$AB$8) -> 0 | M12: =DSUM('KHACH HANG'!$E$5:$R$2133,"8",'KHACH HANG'!$AB$7:$AB$8) -> 0 | N12: =DSUM('KHACH HANG'!$E$5:$R$2133,"9",'KHACH HANG'!$AB$7:$AB$8) -> 0 | O12: =DSUM('KHACH HANG'!$E$5:$R$2133,"10",'KHACH HANG'!$AB$7:$AB$8) -> 0 | P12: =DSUM('KHACH HANG'!$E$5:$R$2133,"11",'KHACH HANG'!$AB$7:$AB$8) -> 0 | Q12: =DSUM('KHACH HANG'!$E$5:$R$2133,"12",'KHACH HANG'!$AB$7:$AB$8) -> 0 | R12: =SUM(F12:Q12) -> 0 | T12: AA | U12: 7 | V12: 8 | W12: DSUM('NHAN VIEN'!$E$5:$Q$2133,"1" | X12: ="DSUM('NHAN VIEN'!$E$5:$Q$2133,"&""""&$X$1&"""" -> DSUM('NHAN VIEN'!$E$5:$Q$2133,"2" | Y12: ="DSUM('NHAN VIEN'!$E$5:$Q$2133,"&""""&$Y$1&"""" -> DSUM('NHAN VIEN'!$E$5:$Q$2133,"3" | Z12: ="DSUM('NHAN VIEN'!$E$5:$Q$2133,"&""""&$Z$1&"""" -> DSUM('NHAN VIEN'!$E$5:$Q$2133,"4" | AA12: ="DSUM('NHAN VIEN'!$E$5:$Q$2133,"&""""&$AA$1&"""" -> DSUM('NHAN VIEN'!$E$5:$Q$2133,"5" | AB12: ="DSUM('NHAN VIEN'!$E$5:$Q$2133,"&""""&$AB$1&"""" -> DSUM('NHAN VIEN'!$E$5:$Q$2133,"6" | AC12: ="DSUM('NHAN VIEN'!$E$5:$Q$2133,"&""""&$AC$1&"""" -> DSUM('NHAN VIEN'!$E$5:$Q$2133,"7" | AD12: ="DSUM('NHAN VIEN'!$E$5:$Q$2133,"&""""&$AD$1&"""" -> DSUM('NHAN VIEN'!$E$5:$Q$2133,"8" | AE12: ="DSUM('NHAN VIEN'!$E$5:$Q$2133,"&""""&$AE$1&"""" -> DSUM('NHAN VIEN'!$E$5:$Q$2133,"9" | AF12: ="DSUM('NHAN VIEN'!$E$5:$Q$2133,"&""""&$AF$1&"""" -> DSUM('NHAN VIEN'!$E$5:$Q$2133,"10" | AG12: ="DSUM('NHAN VIEN'!$E$5:$Q$2133,"&""""&$AG$1&"""" -> DSUM('NHAN VIEN'!$E$5:$Q$2133,"11" | AH12: ="DSUM('NHAN VIEN'!$E$5:$Q$2133,"&""""&$AH$1&"""" -> DSUM('NHAN VIEN'!$E$5:$Q$2133,"12" | AI12: =W12&","&AV12&")" -> DSUM('NHAN VIEN'!$E$5:$Q$2133,"1",'NHAN VIEN'!$AA$7:$AA$8) | AJ12: =X12&","&AV12&")" -> DSUM('NHAN VIEN'!$E$5:$Q$2133,"2",'NHAN VIEN'!$AA$7:$AA$8) | AK12: =Y12&","&AV12&")" -> DSUM('NHAN VIEN'!$E$5:$Q$2133,"3",'NHAN VIEN'!$AA$7:$AA$8) | AL12: =Z12&","&AV12&")" -> DSUM('NHAN VIEN'!$E$5:$Q$2133,"4",'NHAN VIEN'!$AA$7:$AA$8) | AM12: =AA12&","&AV12&")" -> DSUM('NHAN VIEN'!$E$5:$Q$2133,"5",'NHAN VIEN'!$AA$7:$AA$8) | AN12: =AB12&","&AV12&")" -> DSUM('NHAN VIEN'!$E$5:$Q$2133,"6",'NHAN VIEN'!$AA$7:$AA$8) | AO12: =AC12&","&AV12&")" -> DSUM('NHAN VIEN'!$E$5:$Q$2133,"7",'NHAN VIEN'!$AA$7:$AA$8) | AP12: =AD12&","&AV12&")" -> DSUM('NHAN VIEN'!$E$5:$Q$2133,"8",'NHAN VIEN'!$AA$7:$AA$8) | AQ12: =AE12&","&AV12&")" -> DSUM('NHAN VIEN'!$E$5:$Q$2133,"9",'NHAN VIEN'!$AA$7:$AA$8) | AR12: =AF12&","&AV12&")" -> DSUM('NHAN VIEN'!$E$5:$Q$2133,"10",'NHAN VIEN'!$AA$7:$AA$8) | AS12: =AG12&","&AV12&")" -> DSUM('NHAN VIEN'!$E$5:$Q$2133,"11",'NHAN VIEN'!$AA$7:$AA$8) | AT12: =AH12&","&AV12&")" -> DSUM('NHAN VIEN'!$E$5:$Q$2133,"12",'NHAN VIEN'!$AA$7:$AA$8) | AV12: ="'NHAN VIEN'!$"&T12&"$"&U12&":$"&T12&"$"&V12 -> 'NHAN VIEN'!$AA$7:$AA$8 | AY12: ="="&AI12 -> =DSUM('NHAN VIEN'!$E$5:$Q$2133,"1",'NHAN VIEN'!$AA$7:$AA$8) | AZ12: ="="&AJ12 -> =DSUM('NHAN VIEN'!$E$5:$Q$2133,"2",'NHAN VIEN'!$AA$7:$AA$8) | BA12: ="="&AK12 -> =DSUM('NHAN VIEN'!$E$5:$Q$2133,"3",'NHAN VIEN'!$AA$7:$AA$8) | BB12: ="="&AL12 -> =DSUM('NHAN VIEN'!$E$5:$Q$2133,"4",'NHAN VIEN'!$AA$7:$AA$8) | BC12: ="="&AM12 -> =DSUM('NHAN VIEN'!$E$5:$Q$2133,"5",'NHAN VIEN'!$AA$7:$AA$8) | BD12: ="="&AN12 -> =DSUM('NHAN VIEN'!$E$5:$Q$2133,"6",'NHAN VIEN'!$AA$7:$AA$8) | BE12: ="="&AO12 -> =DSUM('NHAN VIEN'!$E$5:$Q$2133,"7",'NHAN VIEN'!$AA$7:$AA$8) | BF12: ="="&AP12 -> =DSUM('NHAN VIEN'!$E$5:$Q$2133,"8",'NHAN VIEN'!$AA$7:$AA$8) | ... BJ12: ="="&AT12 -> =DSUM('NHAN VIEN'!$E$5:$Q$2133,"12",'NHAN VIEN'!$AA$7:$AA$8) | BR12: =R12-'KHACH HANG'!S15 -> 0
B13: =B12+1 -> 11 | C13: =VLOOKUP(B13,DMSP!$A$1:$C$39,2,0) -> 4.DƯỠNG RỄ | D13: =VLOOKUP(B13,DMSP!$A$1:$C$39,3,0) -> ĐẠM TÔM | E13: =R13 -> 0 | F13: =DSUM('KHACH HANG'!$E$5:$R$2133,"1",'KHACH HANG'!$AC$7:$AC$8) -> 0 | G13: =DSUM('KHACH HANG'!$E$5:$R$2133,"2",'KHACH HANG'!$AC$7:$AC$8) -> 0 | H13: =DSUM('KHACH HANG'!$E$5:$R$2133,"3",'KHACH HANG'!$AC$7:$AC$8) -> 0 | I13: =DSUM('KHACH HANG'!$E$5:$R$2133,"4",'KHACH HANG'!$AC$7:$AC$8) -> 0 | J13: =DSUM('KHACH HANG'!$E$5:$R$2133,"5",'KHACH HANG'!$AC$7:$AC$8) -> 0 | K13: =DSUM('KHACH HANG'!$E$5:$R$2133,"6",'KHACH HANG'!$AC$7:$AC$8) -> 0 | L13: =DSUM('KHACH HANG'!$E$5:$R$2133,"7",'KHACH HANG'!$AC$7:$AC$8) -> 0 | M13: =DSUM('KHACH HANG'!$E$5:$R$2133,"8",'KHACH HANG'!$AC$7:$AC$8) -> 0 | N13: =DSUM('KHACH HANG'!$E$5:$R$2133,"9",'KHACH HANG'!$AC$7:$AC$8) -> 0 | O13: =DSUM('KHACH HANG'!$E$5:$R$2133,"10",'KHACH HANG'!$AC$7:$AC$8) -> 0 | P13: =DSUM('KHACH HANG'!$E$5:$R$2133,"11",'KHACH HANG'!$AC$7:$AC$8) -> 0 | Q13: =DSUM('KHACH HANG'!$E$5:$R$2133,"12",'KHACH HANG'!$AC$7:$AC$8) -> 0 | R13: =SUM(F13:Q13) -> 0 | T13: AB | U13: 7 | V13: 8 | W13: DSUM('NHAN VIEN'!$E$5:$Q$2133,"1" | X13: ="DSUM('NHAN VIEN'!$E$5:$Q$2133,"&""""&$X$1&"""" -> DSUM('NHAN VIEN'!$E$5:$Q$2133,"2" | Y13: ="DSUM('NHAN VIEN'!$E$5:$Q$2133,"&""""&$Y$1&"""" -> DSUM('NHAN VIEN'!$E$5:$Q$2133,"3" | Z13: ="DSUM('NHAN VIEN'!$E$5:$Q$2133,"&""""&$Z$1&"""" -> DSUM('NHAN VIEN'!$E$5:$Q$2133,"4" | AA13: ="DSUM('NHAN VIEN'!$E$5:$Q$2133,"&""""&$AA$1&"""" -> DSUM('NHAN VIEN'!$E$5:$Q$2133,"5" | AB13: ="DSUM('NHAN VIEN'!$E$5:$Q$2133,"&""""&$AB$1&"""" -> DSUM('NHAN VIEN'!$E$5:$Q$2133,"6" | AC13: ="DSUM('NHAN VIEN'!$E$5:$Q$2133,"&""""&$AC$1&"""" -> DSUM('NHAN VIEN'!$E$5:$Q$2133,"7" | AD13: ="DSUM('NHAN VIEN'!$E$5:$Q$2133,"&""""&$AD$1&"""" -> DSUM('NHAN VIEN'!$E$5:$Q$2133,"8" | AE13: ="DSUM('NHAN VIEN'!$E$5:$Q$2133,"&""""&$AE$1&"""" -> DSUM('NHAN VIEN'!$E$5:$Q$2133,"9" | AF13: ="DSUM('NHAN VIEN'!$E$5:$Q$2133,"&""""&$AF$1&"""" -> DSUM('NHAN VIEN'!$E$5:$Q$2133,"10" | AG13: ="DSUM('NHAN VIEN'!$E$5:$Q$2133,"&""""&$AG$1&"""" -> DSUM('NHAN VIEN'!$E$5:$Q$2133,"11" | AH13: ="DSUM('NHAN VIEN'!$E$5:$Q$2133,"&""""&$AH$1&"""" -> DSUM('NHAN VIEN'!$E$5:$Q$2133,"12" | AI13: =W13&","&AV13&")" -> DSUM('NHAN VIEN'!$E$5:$Q$2133,"1",'NHAN VIEN'!$AB$7:$AB$8) | AJ13: =X13&","&AV13&")" -> DSUM('NHAN VIEN'!$E$5:$Q$2133,"2",'NHAN VIEN'!$AB$7:$AB$8) | AK13: =Y13&","&AV13&")" -> DSUM('NHAN VIEN'!$E$5:$Q$2133,"3",'NHAN VIEN'!$AB$7:$AB$8) | AL13: =Z13&","&AV13&")" -> DSUM('NHAN VIEN'!$E$5:$Q$2133,"4",'NHAN VIEN'!$AB$7:$AB$8) | AM13: =AA13&","&AV13&")" -> DSUM('NHAN VIEN'!$E$5:$Q$2133,"5",'NHAN VIEN'!$AB$7:$AB$8) | AN13: =AB13&","&AV13&")" -> DSUM('NHAN VIEN'!$E$5:$Q$2133,"6",'NHAN VIEN'!$AB$7:$AB$8) | AO13: =AC13&","&AV13&")" -> DSUM('NHAN VIEN'!$E$5:$Q$2133,"7",'NHAN VIEN'!$AB$7:$AB$8) | AP13: =AD13&","&AV13&")" -> DSUM('NHAN VIEN'!$E$5:$Q$2133,"8",'NHAN VIEN'!$AB$7:$AB$8) | AQ13: =AE13&","&AV13&")" -> DSUM('NHAN VIEN'!$E$5:$Q$2133,"9",'NHAN VIEN'!$AB$7:$AB$8) | AR13: =AF13&","&AV13&")" -> DSUM('NHAN VIEN'!$E$5:$Q$2133,"10",'NHAN VIEN'!$AB$7:$AB$8) | AS13: =AG13&","&AV13&")" -> DSUM('NHAN VIEN'!$E$5:$Q$2133,"11",'NHAN VIEN'!$AB$7:$AB$8) | AT13: =AH13&","&AV13&")" -> DSUM('NHAN VIEN'!$E$5:$Q$2133,"12",'NHAN VIEN'!$AB$7:$AB$8) | AV13: ="'NHAN VIEN'!$"&T13&"$"&U13&":$"&T13&"$"&V13 -> 'NHAN VIEN'!$AB$7:$AB$8 | AY13: ="="&AI13 -> =DSUM('NHAN VIEN'!$E$5:$Q$2133,"1",'NHAN VIEN'!$AB$7:$AB$8) | AZ13: ="="&AJ13 -> =DSUM('NHAN VIEN'!$E$5:$Q$2133,"2",'NHAN VIEN'!$AB$7:$AB$8) | BA13: ="="&AK13 -> =DSUM('NHAN VIEN'!$E$5:$Q$2133,"3",'NHAN VIEN'!$AB$7:$AB$8) | BB13: ="="&AL13 -> =DSUM('NHAN VIEN'!$E$5:$Q$2133,"4",'NHAN VIEN'!$AB$7:$AB$8) | BC13: ="="&AM13 -> =DSUM('NHAN VIEN'!$E$5:$Q$2133,"5",'NHAN VIEN'!$AB$7:$AB$8) | BD13: ="="&AN13 -> =DSUM('NHAN VIEN'!$E$5:$Q$2133,"6",'NHAN VIEN'!$AB$7:$AB$8) | BE13: ="="&AO13 -> =DSUM('NHAN VIEN'!$E$5:$Q$2133,"7",'NHAN VIEN'!$AB$7:$AB$8) | BF13: ="="&AP13 -> =DSUM('NHAN VIEN'!$E$5:$Q$2133,"8",'NHAN VIEN'!$AB$7:$AB$8) | ... BJ13: ="="&AT13 -> =DSUM('NHAN VIEN'!$E$5:$Q$2133,"12",'NHAN VIEN'!$AB$7:$AB$8) | BR13: =R13-'KHACH HANG'!S16 -> 0
